Workbook

Sheet Notes
A1: Autonomic function testing — hospital price transparency summary
A3: Scope | B3: CPT 95921, 95922, 95923, 95924 (autonomic function tests) and 93660 (tilt table, context). Hospitals: MGH, Brigham and Women's, BW Faulkner, Wentworth-Douglass, BIDMC.
A4: Source | B4: Hospital machine-readable files (CMS HPT, schema v3.0.0) found via each system's cms-hpt.txt; normalised in hpt_autonomic_rates.csv (Rates_data tab).
A5: IMPORTANT | B5: These are HOSPITAL FACILITY rates (hospital outpatient department). They bound independent-site rates from above. They are NOT AutoLabs' expected rates.
A6: OPPS Addendum B | B6: CY2026 OPPS Addendum B (July 2026 update) rates are NATIONAL and UNADJUSTED for the Massachusetts wage index.
A7: Physician fee | B7: The 142.57 physician component is the Medicare MPFS professional component (95924 PC 95.23 + 95923 PC 47.34), used as an APPROXIMATION: physician-group rates are not in hospital files.
A8: Headline figures | B8: Where a row carries median / 10th / 90th percentile allowed amounts and a count, the median allowed amount (what was actually paid) is the headline; otherwise the negotiated rate.
A9: Medicare packaging | B9: 95923 has OPPS status indicator Q1: when billed on the same claim as 95924 (SI S) it is packaged and not paid separately. Battery tab shows Medicare both with packaging applied and as listed.
A10: Comparator | B10: Medicare facility comparator = the hospital's own Medicare FFS (APC-priced) row where listed; OPPS Addendum B national otherwise (always for BIDMC). Cross-check in Medicare_check.
A11: Colour key | B11: Blue text = input value; green text = link to another sheet; black = formula; yellow fill = key derived total.
A12: Tabs | B12: By_code_payer · Battery · Multiples · Focus_payers · Coverage · Reconciliation · Medicare_check · QA · Reference · Rates_data

Sheet By_code_payer
A1: Outpatient facility rates by hospital, code and payer (plans grouped within payer and segment)
A2: Included rows only (see QA). Headline = median allowed amount where the file gives one (what was actually paid), otherwise the median negotiated rate. All cells are formulas over Rates_data.
A4: Hospital | B4: Code | C4: Payer (as in file) | D4: Payer family | E4: Segment | F4: Plan count | G4: Min implied $ | H4: Median implied $ | I4: Max implied $ | J4: Share percentage-based | K4: Median allowed (median of plan medians) | L4: Lowest 10th pct allowed | M4: Highest 90th pct allowed | N4: Allowed counts (as in file) | O4: Headline rate | P4: Headline basis
A5: Massachusetts General Hospital | B5: 95921 | C5: UNITED HEALTHCARE [1016] | D5: UnitedHealthcare | E5: Commercial | F5: =COUNTIFS(Rates_data!$B$2:$B$75,$A5,Rates_data!$D$2:$D$75,$B5,Rates_data!$E$2:$E$75,$C5,Rates_data!$G$2:$G$75,$E5,Rates_data!$Y$2:$Y$75,1) -> 1 | G5: =_xlfn.MINIFS(Rates_data!$P$2:$P$75,Rates_data!$B$2:$B$75,$A5,Rates_data!$D$2:$D$75,$B5,Rates_data!$E$2:$E$75,$C5,Rates_data!$G$2:$G$75,$E5,Rates_data!$Y$2:$Y$75,1) -> 500.13 | H5: {=MEDIAN(IF((Rates_data!$B$2:$B$75=$A5)*(Rates_data!$D$2:$D$75=$B5)*(Rates_data!$G$2:$G$75=$E5)*(Rates_data!$E$2:$E$75=$C5)*(Rates_data!$Y$2:$Y$75=1)*(Rates_data!$P$2:$P$75<>""),Rates_data!$P$2:$P$75))} -> 500.13 | I5: =_xlfn.MAXIFS(Rates_data!$P$2:$P$75,Rates_data!$B$2:$B$75,$A5,Rates_data!$D$2:$D$75,$B5,Rates_data!$E$2:$E$75,$C5,Rates_data!$G$2:$G$75,$E5,Rates_data!$Y$2:$Y$75,1) -> 500.13 | J5: =IF(F5=0,"",SUMIFS(Rates_data!$R$2:$R$75,Rates_data!$B$2:$B$75,$A5,Rates_data!$D$2:$D$75,$B5,Rates_data!$E$2:$E$75,$C5,Rates_data!$G$2:$G$75,$E5,Rates_data!$Y$2:$Y$75,1)/F5) -> 1 | K5: {=IF(COUNTIFS(Rates_data!$B$2:$B$75,$A5,Rates_data!$D$2:$D$75,$B5,Rates_data!$E$2:$E$75,$C5,Rates_data!$G$2:$G$75,$E5,Rates_data!$Y$2:$Y$75,1,Rates_data!$S$2:$S$75,"<>")=0,"",MEDIAN(IF((Rates_data!$B$2:$B$75=$A5)*(Rates_data!$D$2:$D$75=$B5)*(Rates_data!$G$2:$G$75=$E5)*(Rates_data!$E$2:$E$75=$C5)*(Rates_data!$Y$2:$Y$75=1)*(Rates_data!$S$2:$S$75<>""),Rates_data!$S$2:$S$75)))} -> 474.04 | L5: =IF(COUNTIFS(Rates_data!$B$2:$B$75,$A5,Rates_data!$D$2:$D$75,$B5,Rates_data!$E$2:$E$75,$C5,Rates_data!$G$2:$G$75,$E5,Rates_data!$Y$2:$Y$75,1,Rates_data!$T$2:$T$75,"<>")=0,"",_xlfn.MINIFS(Rates_data!$T$2:$T$75,Rates_data!$B$2:$B$75,$A5,Rates_data!$D$2:$D$75,$B5,Rates_data!$E$2:$E$75,$C5,Rates_data!$G$2:$G$75,$E5,Rates_data!$Y$2:$Y$75,1)) -> 474.04 | M5: =IF(COUNTIFS(Rates_data!$B$2:$B$75,$A5,Rates_data!$D$2:$D$75,$B5,Rates_data!$E$2:$E$75,$C5,Rates_data!$G$2:$G$75,$E5,Rates_data!$Y$2:$Y$75,1,Rates_data!$U$2:$U$75,"<>")=0,"",_xlfn.MAXIFS(Rates_data!$U$2:$U$75,Rates_data!$B$2:$B$75,$A5,Rates_data!$D$2:$D$75,$B5,Rates_data!$E$2:$E$75,$C5,Rates_data!$G$2:$G$75,$E5,Rates_data!$Y$2:$Y$75,1)) -> 474.04 | N5: 1 through 10 | O5: =IF(K5<>"",K5,H5) -> 474.04 | P5: =IF(K5<>"","median allowed","median negotiated") -> median allowed
A6: Massachusetts General Hospital | B6: 95923 | C6: AETNA [1001] | D6: Aetna | E6: Commercial | F6: =COUNTIFS(Rates_data!$B$2:$B$75,$A6,Rates_data!$D$2:$D$75,$B6,Rates_data!$E$2:$E$75,$C6,Rates_data!$G$2:$G$75,$E6,Rates_data!$Y$2:$Y$75,1) -> 1 | G6: =_xlfn.MINIFS(Rates_data!$P$2:$P$75,Rates_data!$B$2:$B$75,$A6,Rates_data!$D$2:$D$75,$B6,Rates_data!$E$2:$E$75,$C6,Rates_data!$G$2:$G$75,$E6,Rates_data!$Y$2:$Y$75,1) -> 686.13 | H6: {=MEDIAN(IF((Rates_data!$B$2:$B$75=$A6)*(Rates_data!$D$2:$D$75=$B6)*(Rates_data!$G$2:$G$75=$E6)*(Rates_data!$E$2:$E$75=$C6)*(Rates_data!$Y$2:$Y$75=1)*(Rates_data!$P$2:$P$75<>""),Rates_data!$P$2:$P$75))} -> 686.13 | I6: =_xlfn.MAXIFS(Rates_data!$P$2:$P$75,Rates_data!$B$2:$B$75,$A6,Rates_data!$D$2:$D$75,$B6,Rates_data!$E$2:$E$75,$C6,Rates_data!$G$2:$G$75,$E6,Rates_data!$Y$2:$Y$75,1) -> 686.13 | J6: =IF(F6=0,"",SUMIFS(Rates_data!$R$2:$R$75,Rates_data!$B$2:$B$75,$A6,Rates_data!$D$2:$D$75,$B6,Rates_data!$E$2:$E$75,$C6,Rates_data!$G$2:$G$75,$E6,Rates_data!$Y$2:$Y$75,1)/F6) -> 1 | K6: {=IF(COUNTIFS(Rates_data!$B$2:$B$75,$A6,Rates_data!$D$2:$D$75,$B6,Rates_data!$E$2:$E$75,$C6,Rates_data!$G$2:$G$75,$E6,Rates_data!$Y$2:$Y$75,1,Rates_data!$S$2:$S$75,"<>")=0,"",MEDIAN(IF((Rates_data!$B$2:$B$75=$A6)*(Rates_data!$D$2:$D$75=$B6)*(Rates_data!$G$2:$G$75=$E6)*(Rates_data!$E$2:$E$75=$C6)*(Rates_data!$Y$2:$Y$75=1)*(Rates_data!$S$2:$S$75<>""),Rates_data!$S$2:$S$75)))} -> 1212.81 | L6: =IF(COUNTIFS(Rates_data!$B$2:$B$75,$A6,Rates_data!$D$2:$D$75,$B6,Rates_data!$E$2:$E$75,$C6,Rates_data!$G$2:$G$75,$E6,Rates_data!$Y$2:$Y$75,1,Rates_data!$T$2:$T$75,"<>")=0,"",_xlfn.MINIFS(Rates_data!$T$2:$T$75,Rates_data!$B$2:$B$75,$A6,Rates_data!$D$2:$D$75,$B6,Rates_data!$E$2:$E$75,$C6,Rates_data!$G$2:$G$75,$E6,Rates_data!$Y$2:$Y$75,1)) -> 645.18 | M6: =IF(COUNTIFS(Rates_data!$B$2:$B$75,$A6,Rates_data!$D$2:$D$75,$B6,Rates_data!$E$2:$E$75,$C6,Rates_data!$G$2:$G$75,$E6,Rates_data!$Y$2:$Y$75,1,Rates_data!$U$2:$U$75,"<>")=0,"",_xlfn.MAXIFS(Rates_data!$U$2:$U$75,Rates_data!$B$2:$B$75,$A6,Rates_data!$D$2:$D$75,$B6,Rates_data!$E$2:$E$75,$C6,Rates_data!$G$2:$G$75,$E6,Rates_data!$Y$2:$Y$75,1)) -> 1212.81 | N6: 1 through 10 | O6: =IF(K6<>"",K6,H6) -> 1212.81 | P6: =IF(K6<>"","median allowed","median negotiated") -> median allowed
A7: Massachusetts General Hospital | B7: 95923 | C7: CIGNA ALTERNATE [1018] | D7: Cigna | E7: Commercial | F7: =COUNTIFS(Rates_data!$B$2:$B$75,$A7,Rates_data!$D$2:$D$75,$B7,Rates_data!$E$2:$E$75,$C7,Rates_data!$G$2:$G$75,$E7,Rates_data!$Y$2:$Y$75,1) -> 1 | G7: =_xlfn.MINIFS(Rates_data!$P$2:$P$75,Rates_data!$B$2:$B$75,$A7,Rates_data!$D$2:$D$75,$B7,Rates_data!$E$2:$E$75,$C7,Rates_data!$G$2:$G$75,$E7,Rates_data!$Y$2:$Y$75,1) -> 523.94 | H7: {=MEDIAN(IF((Rates_data!$B$2:$B$75=$A7)*(Rates_data!$D$2:$D$75=$B7)*(Rates_data!$G$2:$G$75=$E7)*(Rates_data!$E$2:$E$75=$C7)*(Rates_data!$Y$2:$Y$75=1)*(Rates_data!$P$2:$P$75<>""),Rates_data!$P$2:$P$75))} -> 523.94 | I7: =_xlfn.MAXIFS(Rates_data!$P$2:$P$75,Rates_data!$B$2:$B$75,$A7,Rates_data!$D$2:$D$75,$B7,Rates_data!$E$2:$E$75,$C7,Rates_data!$G$2:$G$75,$E7,Rates_data!$Y$2:$Y$75,1) -> 523.94 | J7: =IF(F7=0,"",SUMIFS(Rates_data!$R$2:$R$75,Rates_data!$B$2:$B$75,$A7,Rates_data!$D$2:$D$75,$B7,Rates_data!$E$2:$E$75,$C7,Rates_data!$G$2:$G$75,$E7,Rates_data!$Y$2:$Y$75,1)/F7) -> 1 | K7: {=IF(COUNTIFS(Rates_data!$B$2:$B$75,$A7,Rates_data!$D$2:$D$75,$B7,Rates_data!$E$2:$E$75,$C7,Rates_data!$G$2:$G$75,$E7,Rates_data!$Y$2:$Y$75,1,Rates_data!$S$2:$S$75,"<>")=0,"",MEDIAN(IF((Rates_data!$B$2:$B$75=$A7)*(Rates_data!$D$2:$D$75=$B7)*(Rates_data!$G$2:$G$75=$E7)*(Rates_data!$E$2:$E$75=$C7)*(Rates_data!$Y$2:$Y$75=1)*(Rates_data!$S$2:$S$75<>""),Rates_data!$S$2:$S$75)))} -> 503.18 | L7: =IF(COUNTIFS(Rates_data!$B$2:$B$75,$A7,Rates_data!$D$2:$D$75,$B7,Rates_data!$E$2:$E$75,$C7,Rates_data!$G$2:$G$75,$E7,Rates_data!$Y$2:$Y$75,1,Rates_data!$T$2:$T$75,"<>")=0,"",_xlfn.MINIFS(Rates_data!$T$2:$T$75,Rates_data!$B$2:$B$75,$A7,Rates_data!$D$2:$D$75,$B7,Rates_data!$E$2:$E$75,$C7,Rates_data!$G$2:$G$75,$E7,Rates_data!$Y$2:$Y$75,1)) -> 503.18 | M7: =IF(COUNTIFS(Rates_data!$B$2:$B$75,$A7,Rates_data!$D$2:$D$75,$B7,Rates_data!$E$2:$E$75,$C7,Rates_data!$G$2:$G$75,$E7,Rates_data!$Y$2:$Y$75,1,Rates_data!$U$2:$U$75,"<>")=0,"",_xlfn.MAXIFS(Rates_data!$U$2:$U$75,Rates_data!$B$2:$B$75,$A7,Rates_data!$D$2:$D$75,$B7,Rates_data!$E$2:$E$75,$C7,Rates_data!$G$2:$G$75,$E7,Rates_data!$Y$2:$Y$75,1)) -> 503.18 | N7: 1 through 10 | O7: =IF(K7<>"",K7,H7) -> 503.18 | P7: =IF(K7<>"","median allowed","median negotiated") -> median allowed
A8: Massachusetts General Hospital | B8: 95923 | C8: CIGNA [1006] | D8: Cigna | E8: Commercial | F8: =COUNTIFS(Rates_data!$B$2:$B$75,$A8,Rates_data!$D$2:$D$75,$B8,Rates_data!$E$2:$E$75,$C8,Rates_data!$G$2:$G$75,$E8,Rates_data!$Y$2:$Y$75,1) -> 1 | G8: =_xlfn.MINIFS(Rates_data!$P$2:$P$75,Rates_data!$B$2:$B$75,$A8,Rates_data!$D$2:$D$75,$B8,Rates_data!$E$2:$E$75,$C8,Rates_data!$G$2:$G$75,$E8,Rates_data!$Y$2:$Y$75,1) -> 781.49 | H8: {=MEDIAN(IF((Rates_data!$B$2:$B$75=$A8)*(Rates_data!$D$2:$D$75=$B8)*(Rates_data!$G$2:$G$75=$E8)*(Rates_data!$E$2:$E$75=$C8)*(Rates_data!$Y$2:$Y$75=1)*(Rates_data!$P$2:$P$75<>""),Rates_data!$P$2:$P$75))} -> 781.49 | I8: =_xlfn.MAXIFS(Rates_data!$P$2:$P$75,Rates_data!$B$2:$B$75,$A8,Rates_data!$D$2:$D$75,$B8,Rates_data!$E$2:$E$75,$C8,Rates_data!$G$2:$G$75,$E8,Rates_data!$Y$2:$Y$75,1) -> 781.49 | J8: =IF(F8=0,"",SUMIFS(Rates_data!$R$2:$R$75,Rates_data!$B$2:$B$75,$A8,Rates_data!$D$2:$D$75,$B8,Rates_data!$E$2:$E$75,$C8,Rates_data!$G$2:$G$75,$E8,Rates_data!$Y$2:$Y$75,1)/F8) -> 1 | K8: {=IF(COUNTIFS(Rates_data!$B$2:$B$75,$A8,Rates_data!$D$2:$D$75,$B8,Rates_data!$E$2:$E$75,$C8,Rates_data!$G$2:$G$75,$E8,Rates_data!$Y$2:$Y$75,1,Rates_data!$S$2:$S$75,"<>")=0,"",MEDIAN(IF((Rates_data!$B$2:$B$75=$A8)*(Rates_data!$D$2:$D$75=$B8)*(Rates_data!$G$2:$G$75=$E8)*(Rates_data!$E$2:$E$75=$C8)*(Rates_data!$Y$2:$Y$75=1)*(Rates_data!$S$2:$S$75<>""),Rates_data!$S$2:$S$75)))} -> 750.01 | L8: =IF(COUNTIFS(Rates_data!$B$2:$B$75,$A8,Rates_data!$D$2:$D$75,$B8,Rates_data!$E$2:$E$75,$C8,Rates_data!$G$2:$G$75,$E8,Rates_data!$Y$2:$Y$75,1,Rates_data!$T$2:$T$75,"<>")=0,"",_xlfn.MINIFS(Rates_data!$T$2:$T$75,Rates_data!$B$2:$B$75,$A8,Rates_data!$D$2:$D$75,$B8,Rates_data!$E$2:$E$75,$C8,Rates_data!$G$2:$G$75,$E8,Rates_data!$Y$2:$Y$75,1)) -> 503.18 | M8: =IF(COUNTIFS(Rates_data!$B$2:$B$75,$A8,Rates_data!$D$2:$D$75,$B8,Rates_data!$E$2:$E$75,$C8,Rates_data!$G$2:$G$75,$E8,Rates_data!$Y$2:$Y$75,1,Rates_data!$U$2:$U$75,"<>")=0,"",_xlfn.MAXIFS(Rates_data!$U$2:$U$75,Rates_data!$B$2:$B$75,$A8,Rates_data!$D$2:$D$75,$B8,Rates_data!$E$2:$E$75,$C8,Rates_data!$G$2:$G$75,$E8,Rates_data!$Y$2:$Y$75,1)) -> 750.01 | N8: 17 | O8: =IF(K8<>"",K8,H8) -> 750.01 | P8: =IF(K8<>"","median allowed","median negotiated") -> median allowed
A9: Massachusetts General Hospital | B9: 95923 | C9: INTERNATIONAL COMMERCIAL [140001] | D9: International commercial | E9: Commercial | F9: =COUNTIFS(Rates_data!$B$2:$B$75,$A9,Rates_data!$D$2:$D$75,$B9,Rates_data!$E$2:$E$75,$C9,Rates_data!$G$2:$G$75,$E9,Rates_data!$Y$2:$Y$75,1) -> 1 | G9: =_xlfn.MINIFS(Rates_data!$P$2:$P$75,Rates_data!$B$2:$B$75,$A9,Rates_data!$D$2:$D$75,$B9,Rates_data!$E$2:$E$75,$C9,Rates_data!$G$2:$G$75,$E9,Rates_data!$Y$2:$Y$75,1) -> 638.95 | H9: {=MEDIAN(IF((Rates_data!$B$2:$B$75=$A9)*(Rates_data!$D$2:$D$75=$B9)*(Rates_data!$G$2:$G$75=$E9)*(Rates_data!$E$2:$E$75=$C9)*(Rates_data!$Y$2:$Y$75=1)*(Rates_data!$P$2:$P$75<>""),Rates_data!$P$2:$P$75))} -> 638.95 | I9: =_xlfn.MAXIFS(Rates_data!$P$2:$P$75,Rates_data!$B$2:$B$75,$A9,Rates_data!$D$2:$D$75,$B9,Rates_data!$E$2:$E$75,$C9,Rates_data!$G$2:$G$75,$E9,Rates_data!$Y$2:$Y$75,1) -> 638.95 | J9: =IF(F9=0,"",SUMIFS(Rates_data!$R$2:$R$75,Rates_data!$B$2:$B$75,$A9,Rates_data!$D$2:$D$75,$B9,Rates_data!$E$2:$E$75,$C9,Rates_data!$G$2:$G$75,$E9,Rates_data!$Y$2:$Y$75,1)/F9) -> 1 | K9: {=IF(COUNTIFS(Rates_data!$B$2:$B$75,$A9,Rates_data!$D$2:$D$75,$B9,Rates_data!$E$2:$E$75,$C9,Rates_data!$G$2:$G$75,$E9,Rates_data!$Y$2:$Y$75,1,Rates_data!$S$2:$S$75,"<>")=0,"",MEDIAN(IF((Rates_data!$B$2:$B$75=$A9)*(Rates_data!$D$2:$D$75=$B9)*(Rates_data!$G$2:$G$75=$E9)*(Rates_data!$E$2:$E$75=$C9)*(Rates_data!$Y$2:$Y$75=1)*(Rates_data!$S$2:$S$75<>""),Rates_data!$S$2:$S$75)))} -> 619.45 | L9: =IF(COUNTIFS(Rates_data!$B$2:$B$75,$A9,Rates_data!$D$2:$D$75,$B9,Rates_data!$E$2:$E$75,$C9,Rates_data!$G$2:$G$75,$E9,Rates_data!$Y$2:$Y$75,1,Rates_data!$T$2:$T$75,"<>")=0,"",_xlfn.MINIFS(Rates_data!$T$2:$T$75,Rates_data!$B$2:$B$75,$A9,Rates_data!$D$2:$D$75,$B9,Rates_data!$E$2:$E$75,$C9,Rates_data!$G$2:$G$75,$E9,Rates_data!$Y$2:$Y$75,1)) -> 619.45 | M9: =IF(COUNTIFS(Rates_data!$B$2:$B$75,$A9,Rates_data!$D$2:$D$75,$B9,Rates_data!$E$2:$E$75,$C9,Rates_data!$G$2:$G$75,$E9,Rates_data!$Y$2:$Y$75,1,Rates_data!$U$2:$U$75,"<>")=0,"",_xlfn.MAXIFS(Rates_data!$U$2:$U$75,Rates_data!$B$2:$B$75,$A9,Rates_data!$D$2:$D$75,$B9,Rates_data!$E$2:$E$75,$C9,Rates_data!$G$2:$G$75,$E9,Rates_data!$Y$2:$Y$75,1)) -> 619.45 | N9: 1 through 10 | O9: =IF(K9<>"",K9,H9) -> 619.45 | P9: =IF(K9<>"","median allowed","median negotiated") -> median allowed
A10: Massachusetts General Hospital | B10: 95923 | C10: MGB HEALTH PLAN [150001] | D10: Mass General Brigham Health Plan | E10: Commercial | F10: =COUNTIFS(Rates_data!$B$2:$B$75,$A10,Rates_data!$D$2:$D$75,$B10,Rates_data!$E$2:$E$75,$C10,Rates_data!$G$2:$G$75,$E10,Rates_data!$Y$2:$Y$75,1) -> 2 | G10: =_xlfn.MINIFS(Rates_data!$P$2:$P$75,Rates_data!$B$2:$B$75,$A10,Rates_data!$D$2:$D$75,$B10,Rates_data!$E$2:$E$75,$C10,Rates_data!$G$2:$G$75,$E10,Rates_data!$Y$2:$Y$75,1) -> 358.8 | H10: {=MEDIAN(IF((Rates_data!$B$2:$B$75=$A10)*(Rates_data!$D$2:$D$75=$B10)*(Rates_data!$G$2:$G$75=$E10)*(Rates_data!$E$2:$E$75=$C10)*(Rates_data!$Y$2:$Y$75=1)*(Rates_data!$P$2:$P$75<>""),Rates_data!$P$2:$P$75))} -> 367.645 | I10: =_xlfn.MAXIFS(Rates_data!$P$2:$P$75,Rates_data!$B$2:$B$75,$A10,Rates_data!$D$2:$D$75,$B10,Rates_data!$E$2:$E$75,$C10,Rates_data!$G$2:$G$75,$E10,Rates_data!$Y$2:$Y$75,1) -> 376.49 | J10: =IF(F10=0,"",SUMIFS(Rates_data!$R$2:$R$75,Rates_data!$B$2:$B$75,$A10,Rates_data!$D$2:$D$75,$B10,Rates_data!$E$2:$E$75,$C10,Rates_data!$G$2:$G$75,$E10,Rates_data!$Y$2:$Y$75,1)/F10) -> 1 | K10: {=IF(COUNTIFS(Rates_data!$B$2:$B$75,$A10,Rates_data!$D$2:$D$75,$B10,Rates_data!$E$2:$E$75,$C10,Rates_data!$G$2:$G$75,$E10,Rates_data!$Y$2:$Y$75,1,Rates_data!$S$2:$S$75,"<>")=0,"",MEDIAN(IF((Rates_data!$B$2:$B$75=$A10)*(Rates_data!$D$2:$D$75=$B10)*(Rates_data!$G$2:$G$75=$E10)*(Rates_data!$E$2:$E$75=$C10)*(Rates_data!$Y$2:$Y$75=1)*(Rates_data!$S$2:$S$75<>""),Rates_data!$S$2:$S$75)))} -> 364.045 | L10: =IF(COUNTIFS(Rates_data!$B$2:$B$75,$A10,Rates_data!$D$2:$D$75,$B10,Rates_data!$E$2:$E$75,$C10,Rates_data!$G$2:$G$75,$E10,Rates_data!$Y$2:$Y$75,1,Rates_data!$T$2:$T$75,"<>")=0,"",_xlfn.MINIFS(Rates_data!$T$2:$T$75,Rates_data!$B$2:$B$75,$A10,Rates_data!$D$2:$D$75,$B10,Rates_data!$E$2:$E$75,$C10,Rates_data!$G$2:$G$75,$E10,Rates_data!$Y$2:$Y$75,1)) -> 302.1 | M10: =IF(COUNTIFS(Rates_data!$B$2:$B$75,$A10,Rates_data!$D$2:$D$75,$B10,Rates_data!$E$2:$E$75,$C10,Rates_data!$G$2:$G$75,$E10,Rates_data!$Y$2:$Y$75,1,Rates_data!$U$2:$U$75,"<>")=0,"",_xlfn.MAXIFS(Rates_data!$U$2:$U$75,Rates_data!$B$2:$B$75,$A10,Rates_data!$D$2:$D$75,$B10,Rates_data!$E$2:$E$75,$C10,Rates_data!$G$2:$G$75,$E10,Rates_data!$Y$2:$Y$75,1)) -> 372.62 | N10: 13; 36 | O10: =IF(K10<>"",K10,H10) -> 364.045 | P10: =IF(K10<>"","median allowed","median negotiated") -> median allowed
A11: Massachusetts General Hospital | B11: 95923 | C11: UNITED HEALTHCARE [1016] | D11: UnitedHealthcare | E11: Commercial | F11: =COUNTIFS(Rates_data!$B$2:$B$75,$A11,Rates_data!$D$2:$D$75,$B11,Rates_data!$E$2:$E$75,$C11,Rates_data!$G$2:$G$75,$E11,Rates_data!$Y$2:$Y$75,1) -> 2 | G11: =_xlfn.MINIFS(Rates_data!$P$2:$P$75,Rates_data!$B$2:$B$75,$A11,Rates_data!$D$2:$D$75,$B11,Rates_data!$E$2:$E$75,$C11,Rates_data!$G$2:$G$75,$E11,Rates_data!$Y$2:$Y$75,1) -> 421.71 | H11: {=MEDIAN(IF((Rates_data!$B$2:$B$75=$A11)*(Rates_data!$D$2:$D$75=$B11)*(Rates_data!$G$2:$G$75=$E11)*(Rates_data!$E$2:$E$75=$C11)*(Rates_data!$Y$2:$Y$75=1)*(Rates_data!$P$2:$P$75<>""),Rates_data!$P$2:$P$75))} -> 612.51 | I11: =_xlfn.MAXIFS(Rates_data!$P$2:$P$75,Rates_data!$B$2:$B$75,$A11,Rates_data!$D$2:$D$75,$B11,Rates_data!$E$2:$E$75,$C11,Rates_data!$G$2:$G$75,$E11,Rates_data!$Y$2:$Y$75,1) -> 803.31 | J11: =IF(F11=0,"",SUMIFS(Rates_data!$R$2:$R$75,Rates_data!$B$2:$B$75,$A11,Rates_data!$D$2:$D$75,$B11,Rates_data!$E$2:$E$75,$C11,Rates_data!$G$2:$G$75,$E11,Rates_data!$Y$2:$Y$75,1)/F11) -> 1 | K11: {=IF(COUNTIFS(Rates_data!$B$2:$B$75,$A11,Rates_data!$D$2:$D$75,$B11,Rates_data!$E$2:$E$75,$C11,Rates_data!$G$2:$G$75,$E11,Rates_data!$Y$2:$Y$75,1,Rates_data!$S$2:$S$75,"<>")=0,"",MEDIAN(IF((Rates_data!$B$2:$B$75=$A11)*(Rates_data!$D$2:$D$75=$B11)*(Rates_data!$G$2:$G$75=$E11)*(Rates_data!$E$2:$E$75=$C11)*(Rates_data!$Y$2:$Y$75=1)*(Rates_data!$S$2:$S$75<>""),Rates_data!$S$2:$S$75)))} -> 761.83 | L11: =IF(COUNTIFS(Rates_data!$B$2:$B$75,$A11,Rates_data!$D$2:$D$75,$B11,Rates_data!$E$2:$E$75,$C11,Rates_data!$G$2:$G$75,$E11,Rates_data!$Y$2:$Y$75,1,Rates_data!$T$2:$T$75,"<>")=0,"",_xlfn.MINIFS(Rates_data!$T$2:$T$75,Rates_data!$B$2:$B$75,$A11,Rates_data!$D$2:$D$75,$B11,Rates_data!$E$2:$E$75,$C11,Rates_data!$G$2:$G$75,$E11,Rates_data!$Y$2:$Y$75,1)) -> 761.83 | M11: =IF(COUNTIFS(Rates_data!$B$2:$B$75,$A11,Rates_data!$D$2:$D$75,$B11,Rates_data!$E$2:$E$75,$C11,Rates_data!$G$2:$G$75,$E11,Rates_data!$Y$2:$Y$75,1,Rates_data!$U$2:$U$75,"<>")=0,"",_xlfn.MAXIFS(Rates_data!$U$2:$U$75,Rates_data!$B$2:$B$75,$A11,Rates_data!$D$2:$D$75,$B11,Rates_data!$E$2:$E$75,$C11,Rates_data!$G$2:$G$75,$E11,Rates_data!$Y$2:$Y$75,1)) -> 1212.81 | N11: 1 through 10; 18 | O11: =IF(K11<>"",K11,H11) -> 761.83 | P11: =IF(K11<>"","median allowed","median negotiated") -> median allowed
A12: Massachusetts General Hospital | B12: 95923 | C12: WELLPOINT [1015] | D12: Wellpoint | E12: Commercial | F12: =COUNTIFS(Rates_data!$B$2:$B$75,$A12,Rates_data!$D$2:$D$75,$B12,Rates_data!$E$2:$E$75,$C12,Rates_data!$G$2:$G$75,$E12,Rates_data!$Y$2:$Y$75,1) -> 1 | G12: =_xlfn.MINIFS(Rates_data!$P$2:$P$75,Rates_data!$B$2:$B$75,$A12,Rates_data!$D$2:$D$75,$B12,Rates_data!$E$2:$E$75,$C12,Rates_data!$G$2:$G$75,$E12,Rates_data!$Y$2:$Y$75,1) -> 725.26 | H12: {=MEDIAN(IF((Rates_data!$B$2:$B$75=$A12)*(Rates_data!$D$2:$D$75=$B12)*(Rates_data!$G$2:$G$75=$E12)*(Rates_data!$E$2:$E$75=$C12)*(Rates_data!$Y$2:$Y$75=1)*(Rates_data!$P$2:$P$75<>""),Rates_data!$P$2:$P$75))} -> 725.26 | I12: =_xlfn.MAXIFS(Rates_data!$P$2:$P$75,Rates_data!$B$2:$B$75,$A12,Rates_data!$D$2:$D$75,$B12,Rates_data!$E$2:$E$75,$C12,Rates_data!$G$2:$G$75,$E12,Rates_data!$Y$2:$Y$75,1) -> 725.26 | J12: =IF(F12=0,"",SUMIFS(Rates_data!$R$2:$R$75,Rates_data!$B$2:$B$75,$A12,Rates_data!$D$2:$D$75,$B12,Rates_data!$E$2:$E$75,$C12,Rates_data!$G$2:$G$75,$E12,Rates_data!$Y$2:$Y$75,1)/F12) -> 1 | K12: {=IF(COUNTIFS(Rates_data!$B$2:$B$75,$A12,Rates_data!$D$2:$D$75,$B12,Rates_data!$E$2:$E$75,$C12,Rates_data!$G$2:$G$75,$E12,Rates_data!$Y$2:$Y$75,1,Rates_data!$S$2:$S$75,"<>")=0,"",MEDIAN(IF((Rates_data!$B$2:$B$75=$A12)*(Rates_data!$D$2:$D$75=$B12)*(Rates_data!$G$2:$G$75=$E12)*(Rates_data!$E$2:$E$75=$C12)*(Rates_data!$Y$2:$Y$75=1)*(Rates_data!$S$2:$S$75<>""),Rates_data!$S$2:$S$75)))} -> 709.51 | L12: =IF(COUNTIFS(Rates_data!$B$2:$B$75,$A12,Rates_data!$D$2:$D$75,$B12,Rates_data!$E$2:$E$75,$C12,Rates_data!$G$2:$G$75,$E12,Rates_data!$Y$2:$Y$75,1,Rates_data!$T$2:$T$75,"<>")=0,"",_xlfn.MINIFS(Rates_data!$T$2:$T$75,Rates_data!$B$2:$B$75,$A12,Rates_data!$D$2:$D$75,$B12,Rates_data!$E$2:$E$75,$C12,Rates_data!$G$2:$G$75,$E12,Rates_data!$Y$2:$Y$75,1)) -> 709.51 | M12: =IF(COUNTIFS(Rates_data!$B$2:$B$75,$A12,Rates_data!$D$2:$D$75,$B12,Rates_data!$E$2:$E$75,$C12,Rates_data!$G$2:$G$75,$E12,Rates_data!$Y$2:$Y$75,1,Rates_data!$U$2:$U$75,"<>")=0,"",_xlfn.MAXIFS(Rates_data!$U$2:$U$75,Rates_data!$B$2:$B$75,$A12,Rates_data!$D$2:$D$75,$B12,Rates_data!$E$2:$E$75,$C12,Rates_data!$G$2:$G$75,$E12,Rates_data!$Y$2:$Y$75,1)) -> 709.51 | N12: 1 through 10 | O12: =IF(K12<>"",K12,H12) -> 709.51 | P12: =IF(K12<>"","median allowed","median negotiated") -> median allowed
A13: Massachusetts General Hospital | B13: 95924 | C13: AETNA [1001] | D13: Aetna | E13: Commercial | F13: =COUNTIFS(Rates_data!$B$2:$B$75,$A13,Rates_data!$D$2:$D$75,$B13,Rates_data!$E$2:$E$75,$C13,Rates_data!$G$2:$G$75,$E13,Rates_data!$Y$2:$Y$75,1) -> 1 | G13: =_xlfn.MINIFS(Rates_data!$P$2:$P$75,Rates_data!$B$2:$B$75,$A13,Rates_data!$D$2:$D$75,$B13,Rates_data!$E$2:$E$75,$C13,Rates_data!$G$2:$G$75,$E13,Rates_data!$Y$2:$Y$75,1) -> 801.3 | H13: {=MEDIAN(IF((Rates_data!$B$2:$B$75=$A13)*(Rates_data!$D$2:$D$75=$B13)*(Rates_data!$G$2:$G$75=$E13)*(Rates_data!$E$2:$E$75=$C13)*(Rates_data!$Y$2:$Y$75=1)*(Rates_data!$P$2:$P$75<>""),Rates_data!$P$2:$P$75))} -> 801.3 | I13: =_xlfn.MAXIFS(Rates_data!$P$2:$P$75,Rates_data!$B$2:$B$75,$A13,Rates_data!$D$2:$D$75,$B13,Rates_data!$E$2:$E$75,$C13,Rates_data!$G$2:$G$75,$E13,Rates_data!$Y$2:$Y$75,1) -> 801.3 | J13: =IF(F13=0,"",SUMIFS(Rates_data!$R$2:$R$75,Rates_data!$B$2:$B$75,$A13,Rates_data!$D$2:$D$75,$B13,Rates_data!$E$2:$E$75,$C13,Rates_data!$G$2:$G$75,$E13,Rates_data!$Y$2:$Y$75,1)/F13) -> 1 | K13: {=IF(COUNTIFS(Rates_data!$B$2:$B$75,$A13,Rates_data!$D$2:$D$75,$B13,Rates_data!$E$2:$E$75,$C13,Rates_data!$G$2:$G$75,$E13,Rates_data!$Y$2:$Y$75,1,Rates_data!$S$2:$S$75,"<>")=0,"",MEDIAN(IF((Rates_data!$B$2:$B$75=$A13)*(Rates_data!$D$2:$D$75=$B13)*(Rates_data!$G$2:$G$75=$E13)*(Rates_data!$E$2:$E$75=$C13)*(Rates_data!$Y$2:$Y$75=1)*(Rates_data!$S$2:$S$75<>""),Rates_data!$S$2:$S$75)))} -> 1444.72 | L13: =IF(COUNTIFS(Rates_data!$B$2:$B$75,$A13,Rates_data!$D$2:$D$75,$B13,Rates_data!$E$2:$E$75,$C13,Rates_data!$G$2:$G$75,$E13,Rates_data!$Y$2:$Y$75,1,Rates_data!$T$2:$T$75,"<>")=0,"",_xlfn.MINIFS(Rates_data!$T$2:$T$75,Rates_data!$B$2:$B$75,$A13,Rates_data!$D$2:$D$75,$B13,Rates_data!$E$2:$E$75,$C13,Rates_data!$G$2:$G$75,$E13,Rates_data!$Y$2:$Y$75,1)) -> 753.5 | M13: =IF(COUNTIFS(Rates_data!$B$2:$B$75,$A13,Rates_data!$D$2:$D$75,$B13,Rates_data!$E$2:$E$75,$C13,Rates_data!$G$2:$G$75,$E13,Rates_data!$Y$2:$Y$75,1,Rates_data!$U$2:$U$75,"<>")=0,"",_xlfn.MAXIFS(Rates_data!$U$2:$U$75,Rates_data!$B$2:$B$75,$A13,Rates_data!$D$2:$D$75,$B13,Rates_data!$E$2:$E$75,$C13,Rates_data!$G$2:$G$75,$E13,Rates_data!$Y$2:$Y$75,1)) -> 1444.72 | N13: 1 through 10 | O13: =IF(K13<>"",K13,H13) -> 1444.72 | P13: =IF(K13<>"","median allowed","median negotiated") -> median allowed
A14: Massachusetts General Hospital | B14: 95924 | C14: CIGNA ALTERNATE [1018] | D14: Cigna | E14: Commercial | F14: =COUNTIFS(Rates_data!$B$2:$B$75,$A14,Rates_data!$D$2:$D$75,$B14,Rates_data!$E$2:$E$75,$C14,Rates_data!$G$2:$G$75,$E14,Rates_data!$Y$2:$Y$75,1) -> 1 | G14: =_xlfn.MINIFS(Rates_data!$P$2:$P$75,Rates_data!$B$2:$B$75,$A14,Rates_data!$D$2:$D$75,$B14,Rates_data!$E$2:$E$75,$C14,Rates_data!$G$2:$G$75,$E14,Rates_data!$Y$2:$Y$75,1) -> 611.88 | H14: {=MEDIAN(IF((Rates_data!$B$2:$B$75=$A14)*(Rates_data!$D$2:$D$75=$B14)*(Rates_data!$G$2:$G$75=$E14)*(Rates_data!$E$2:$E$75=$C14)*(Rates_data!$Y$2:$Y$75=1)*(Rates_data!$P$2:$P$75<>""),Rates_data!$P$2:$P$75))} -> 611.88 | I14: =_xlfn.MAXIFS(Rates_data!$P$2:$P$75,Rates_data!$B$2:$B$75,$A14,Rates_data!$D$2:$D$75,$B14,Rates_data!$E$2:$E$75,$C14,Rates_data!$G$2:$G$75,$E14,Rates_data!$Y$2:$Y$75,1) -> 611.88 | J14: =IF(F14=0,"",SUMIFS(Rates_data!$R$2:$R$75,Rates_data!$B$2:$B$75,$A14,Rates_data!$D$2:$D$75,$B14,Rates_data!$E$2:$E$75,$C14,Rates_data!$G$2:$G$75,$E14,Rates_data!$Y$2:$Y$75,1)/F14) -> 1 | K14: {=IF(COUNTIFS(Rates_data!$B$2:$B$75,$A14,Rates_data!$D$2:$D$75,$B14,Rates_data!$E$2:$E$75,$C14,Rates_data!$G$2:$G$75,$E14,Rates_data!$Y$2:$Y$75,1,Rates_data!$S$2:$S$75,"<>")=0,"",MEDIAN(IF((Rates_data!$B$2:$B$75=$A14)*(Rates_data!$D$2:$D$75=$B14)*(Rates_data!$G$2:$G$75=$E14)*(Rates_data!$E$2:$E$75=$C14)*(Rates_data!$Y$2:$Y$75=1)*(Rates_data!$S$2:$S$75<>""),Rates_data!$S$2:$S$75)))} -> 587.66 | L14: =IF(COUNTIFS(Rates_data!$B$2:$B$75,$A14,Rates_data!$D$2:$D$75,$B14,Rates_data!$E$2:$E$75,$C14,Rates_data!$G$2:$G$75,$E14,Rates_data!$Y$2:$Y$75,1,Rates_data!$T$2:$T$75,"<>")=0,"",_xlfn.MINIFS(Rates_data!$T$2:$T$75,Rates_data!$B$2:$B$75,$A14,Rates_data!$D$2:$D$75,$B14,Rates_data!$E$2:$E$75,$C14,Rates_data!$G$2:$G$75,$E14,Rates_data!$Y$2:$Y$75,1)) -> 587.66 | M14: =IF(COUNTIFS(Rates_data!$B$2:$B$75,$A14,Rates_data!$D$2:$D$75,$B14,Rates_data!$E$2:$E$75,$C14,Rates_data!$G$2:$G$75,$E14,Rates_data!$Y$2:$Y$75,1,Rates_data!$U$2:$U$75,"<>")=0,"",_xlfn.MAXIFS(Rates_data!$U$2:$U$75,Rates_data!$B$2:$B$75,$A14,Rates_data!$D$2:$D$75,$B14,Rates_data!$E$2:$E$75,$C14,Rates_data!$G$2:$G$75,$E14,Rates_data!$Y$2:$Y$75,1)) -> 587.66 | N14: 1 through 10 | O14: =IF(K14<>"",K14,H14) -> 587.66 | P14: =IF(K14<>"","median allowed","median negotiated") -> median allowed
A15: Massachusetts General Hospital | B15: 95924 | C15: CIGNA [1006] | D15: Cigna | E15: Commercial | F15: =COUNTIFS(Rates_data!$B$2:$B$75,$A15,Rates_data!$D$2:$D$75,$B15,Rates_data!$E$2:$E$75,$C15,Rates_data!$G$2:$G$75,$E15,Rates_data!$Y$2:$Y$75,1) -> 1 | G15: =_xlfn.MINIFS(Rates_data!$P$2:$P$75,Rates_data!$B$2:$B$75,$A15,Rates_data!$D$2:$D$75,$B15,Rates_data!$E$2:$E$75,$C15,Rates_data!$G$2:$G$75,$E15,Rates_data!$Y$2:$Y$75,1) -> 912.66 | H15: {=MEDIAN(IF((Rates_data!$B$2:$B$75=$A15)*(Rates_data!$D$2:$D$75=$B15)*(Rates_data!$G$2:$G$75=$E15)*(Rates_data!$E$2:$E$75=$C15)*(Rates_data!$Y$2:$Y$75=1)*(Rates_data!$P$2:$P$75<>""),Rates_data!$P$2:$P$75))} -> 912.66 | I15: =_xlfn.MAXIFS(Rates_data!$P$2:$P$75,Rates_data!$B$2:$B$75,$A15,Rates_data!$D$2:$D$75,$B15,Rates_data!$E$2:$E$75,$C15,Rates_data!$G$2:$G$75,$E15,Rates_data!$Y$2:$Y$75,1) -> 912.66 | J15: =IF(F15=0,"",SUMIFS(Rates_data!$R$2:$R$75,Rates_data!$B$2:$B$75,$A15,Rates_data!$D$2:$D$75,$B15,Rates_data!$E$2:$E$75,$C15,Rates_data!$G$2:$G$75,$E15,Rates_data!$Y$2:$Y$75,1)/F15) -> 1 | K15: {=IF(COUNTIFS(Rates_data!$B$2:$B$75,$A15,Rates_data!$D$2:$D$75,$B15,Rates_data!$E$2:$E$75,$C15,Rates_data!$G$2:$G$75,$E15,Rates_data!$Y$2:$Y$75,1,Rates_data!$S$2:$S$75,"<>")=0,"",MEDIAN(IF((Rates_data!$B$2:$B$75=$A15)*(Rates_data!$D$2:$D$75=$B15)*(Rates_data!$G$2:$G$75=$E15)*(Rates_data!$E$2:$E$75=$C15)*(Rates_data!$Y$2:$Y$75=1)*(Rates_data!$S$2:$S$75<>""),Rates_data!$S$2:$S$75)))} -> 875.93 | L15: =IF(COUNTIFS(Rates_data!$B$2:$B$75,$A15,Rates_data!$D$2:$D$75,$B15,Rates_data!$E$2:$E$75,$C15,Rates_data!$G$2:$G$75,$E15,Rates_data!$Y$2:$Y$75,1,Rates_data!$T$2:$T$75,"<>")=0,"",_xlfn.MINIFS(Rates_data!$T$2:$T$75,Rates_data!$B$2:$B$75,$A15,Rates_data!$D$2:$D$75,$B15,Rates_data!$E$2:$E$75,$C15,Rates_data!$G$2:$G$75,$E15,Rates_data!$Y$2:$Y$75,1)) -> 587.66 | M15: =IF(COUNTIFS(Rates_data!$B$2:$B$75,$A15,Rates_data!$D$2:$D$75,$B15,Rates_data!$E$2:$E$75,$C15,Rates_data!$G$2:$G$75,$E15,Rates_data!$Y$2:$Y$75,1,Rates_data!$U$2:$U$75,"<>")=0,"",_xlfn.MAXIFS(Rates_data!$U$2:$U$75,Rates_data!$B$2:$B$75,$A15,Rates_data!$D$2:$D$75,$B15,Rates_data!$E$2:$E$75,$C15,Rates_data!$G$2:$G$75,$E15,Rates_data!$Y$2:$Y$75,1)) -> 875.93 | N15: 18 | O15: =IF(K15<>"",K15,H15) -> 875.93 | P15: =IF(K15<>"","median allowed","median negotiated") -> median allowed
A16: Massachusetts General Hospital | B16: 95924 | C16: INTERNATIONAL COMMERCIAL [140001] | D16: International commercial | E16: Commercial | F16: =COUNTIFS(Rates_data!$B$2:$B$75,$A16,Rates_data!$D$2:$D$75,$B16,Rates_data!$E$2:$E$75,$C16,Rates_data!$G$2:$G$75,$E16,Rates_data!$Y$2:$Y$75,1) -> 1 | G16: =_xlfn.MINIFS(Rates_data!$P$2:$P$75,Rates_data!$B$2:$B$75,$A16,Rates_data!$D$2:$D$75,$B16,Rates_data!$E$2:$E$75,$C16,Rates_data!$G$2:$G$75,$E16,Rates_data!$Y$2:$Y$75,1) -> 746.2 | H16: {=MEDIAN(IF((Rates_data!$B$2:$B$75=$A16)*(Rates_data!$D$2:$D$75=$B16)*(Rates_data!$G$2:$G$75=$E16)*(Rates_data!$E$2:$E$75=$C16)*(Rates_data!$Y$2:$Y$75=1)*(Rates_data!$P$2:$P$75<>""),Rates_data!$P$2:$P$75))} -> 746.2 | I16: =_xlfn.MAXIFS(Rates_data!$P$2:$P$75,Rates_data!$B$2:$B$75,$A16,Rates_data!$D$2:$D$75,$B16,Rates_data!$E$2:$E$75,$C16,Rates_data!$G$2:$G$75,$E16,Rates_data!$Y$2:$Y$75,1) -> 746.2 | J16: =IF(F16=0,"",SUMIFS(Rates_data!$R$2:$R$75,Rates_data!$B$2:$B$75,$A16,Rates_data!$D$2:$D$75,$B16,Rates_data!$E$2:$E$75,$C16,Rates_data!$G$2:$G$75,$E16,Rates_data!$Y$2:$Y$75,1)/F16) -> 1 | K16: {=IF(COUNTIFS(Rates_data!$B$2:$B$75,$A16,Rates_data!$D$2:$D$75,$B16,Rates_data!$E$2:$E$75,$C16,Rates_data!$G$2:$G$75,$E16,Rates_data!$Y$2:$Y$75,1,Rates_data!$S$2:$S$75,"<>")=0,"",MEDIAN(IF((Rates_data!$B$2:$B$75=$A16)*(Rates_data!$D$2:$D$75=$B16)*(Rates_data!$G$2:$G$75=$E16)*(Rates_data!$E$2:$E$75=$C16)*(Rates_data!$Y$2:$Y$75=1)*(Rates_data!$S$2:$S$75<>""),Rates_data!$S$2:$S$75)))} -> 723.45 | L16: =IF(COUNTIFS(Rates_data!$B$2:$B$75,$A16,Rates_data!$D$2:$D$75,$B16,Rates_data!$E$2:$E$75,$C16,Rates_data!$G$2:$G$75,$E16,Rates_data!$Y$2:$Y$75,1,Rates_data!$T$2:$T$75,"<>")=0,"",_xlfn.MINIFS(Rates_data!$T$2:$T$75,Rates_data!$B$2:$B$75,$A16,Rates_data!$D$2:$D$75,$B16,Rates_data!$E$2:$E$75,$C16,Rates_data!$G$2:$G$75,$E16,Rates_data!$Y$2:$Y$75,1)) -> 723.45 | M16: =IF(COUNTIFS(Rates_data!$B$2:$B$75,$A16,Rates_data!$D$2:$D$75,$B16,Rates_data!$E$2:$E$75,$C16,Rates_data!$G$2:$G$75,$E16,Rates_data!$Y$2:$Y$75,1,Rates_data!$U$2:$U$75,"<>")=0,"",_xlfn.MAXIFS(Rates_data!$U$2:$U$75,Rates_data!$B$2:$B$75,$A16,Rates_data!$D$2:$D$75,$B16,Rates_data!$E$2:$E$75,$C16,Rates_data!$G$2:$G$75,$E16,Rates_data!$Y$2:$Y$75,1)) -> 723.45 | N16: 1 through 10 | O16: =IF(K16<>"",K16,H16) -> 723.45 | P16: =IF(K16<>"","median allowed","median negotiated") -> median allowed
... A51: Brigham and Women's Faulkner Hospital | B51: 95924 | C51: TRICARE [160005] | D51: TRICARE | E51: TRICARE | F51: =COUNTIFS(Rates_data!$B$2:$B$75,$A51,Rates_data!$D$2:$D$75,$B51,Rates_data!$E$2:$E$75,$C51,Rates_data!$G$2:$G$75,$E51,Rates_data!$Y$2:$Y$75,1) -> 1 | G51: =_xlfn.MINIFS(Rates_data!$P$2:$P$75,Rates_data!$B$2:$B$75,$A51,Rates_data!$D$2:$D$75,$B51,Rates_data!$E$2:$E$75,$C51,Rates_data!$G$2:$G$75,$E51,Rates_data!$Y$2:$Y$75,1) -> 351.32 | H51: {=MEDIAN(IF((Rates_data!$B$2:$B$75=$A51)*(Rates_data!$D$2:$D$75=$B51)*(Rates_data!$G$2:$G$75=$E51)*(Rates_data!$E$2:$E$75=$C51)*(Rates_data!$Y$2:$Y$75=1)*(Rates_data!$P$2:$P$75<>""),Rates_data!$P$2:$P$75))} -> 351.32 | I51: =_xlfn.MAXIFS(Rates_data!$P$2:$P$75,Rates_data!$B$2:$B$75,$A51,Rates_data!$D$2:$D$75,$B51,Rates_data!$E$2:$E$75,$C51,Rates_data!$G$2:$G$75,$E51,Rates_data!$Y$2:$Y$75,1) -> 351.32 | J51: =IF(F51=0,"",SUMIFS(Rates_data!$R$2:$R$75,Rates_data!$B$2:$B$75,$A51,Rates_data!$D$2:$D$75,$B51,Rates_data!$E$2:$E$75,$C51,Rates_data!$G$2:$G$75,$E51,Rates_data!$Y$2:$Y$75,1)/F51) -> 0 | K51: {=IF(COUNTIFS(Rates_data!$B$2:$B$75,$A51,Rates_data!$D$2:$D$75,$B51,Rates_data!$E$2:$E$75,$C51,Rates_data!$G$2:$G$75,$E51,Rates_data!$Y$2:$Y$75,1,Rates_data!$S$2:$S$75,"<>")=0,"",MEDIAN(IF((Rates_data!$B$2:$B$75=$A51)*(Rates_data!$D$2:$D$75=$B51)*(Rates_data!$G$2:$G$75=$E51)*(Rates_data!$E$2:$E$75=$C51)*(Rates_data!$Y$2:$Y$75=1)*(Rates_data!$S$2:$S$75<>""),Rates_data!$S$2:$S$75)))} -> 351.32 | L51: =IF(COUNTIFS(Rates_data!$B$2:$B$75,$A51,Rates_data!$D$2:$D$75,$B51,Rates_data!$E$2:$E$75,$C51,Rates_data!$G$2:$G$75,$E51,Rates_data!$Y$2:$Y$75,1,Rates_data!$T$2:$T$75,"<>")=0,"",_xlfn.MINIFS(Rates_data!$T$2:$T$75,Rates_data!$B$2:$B$75,$A51,Rates_data!$D$2:$D$75,$B51,Rates_data!$E$2:$E$75,$C51,Rates_data!$G$2:$G$75,$E51,Rates_data!$Y$2:$Y$75,1)) -> 351.32 | M51: =IF(COUNTIFS(Rates_data!$B$2:$B$75,$A51,Rates_data!$D$2:$D$75,$B51,Rates_data!$E$2:$E$75,$C51,Rates_data!$G$2:$G$75,$E51,Rates_data!$Y$2:$Y$75,1,Rates_data!$U$2:$U$75,"<>")=0,"",_xlfn.MAXIFS(Rates_data!$U$2:$U$75,Rates_data!$B$2:$B$75,$A51,Rates_data!$D$2:$D$75,$B51,Rates_data!$E$2:$E$75,$C51,Rates_data!$G$2:$G$75,$E51,Rates_data!$Y$2:$Y$75,1)) -> 351.32 | N51: 1 through 10 | O51: =IF(K51<>"",K51,H51) -> 351.32 | P51: =IF(K51<>"","median allowed","median negotiated") -> median allowed
A52: Beth Israel Deaconess Medical Center | B52: 93660 | C52: BCBS | D52: Blue Cross Blue Shield of MA | E52: Commercial | F52: =COUNTIFS(Rates_data!$B$2:$B$75,$A52,Rates_data!$D$2:$D$75,$B52,Rates_data!$E$2:$E$75,$C52,Rates_data!$G$2:$G$75,$E52,Rates_data!$Y$2:$Y$75,1) -> 2 | G52: =_xlfn.MINIFS(Rates_data!$P$2:$P$75,Rates_data!$B$2:$B$75,$A52,Rates_data!$D$2:$D$75,$B52,Rates_data!$E$2:$E$75,$C52,Rates_data!$G$2:$G$75,$E52,Rates_data!$Y$2:$Y$75,1) -> 1091.24 | H52: {=MEDIAN(IF((Rates_data!$B$2:$B$75=$A52)*(Rates_data!$D$2:$D$75=$B52)*(Rates_data!$G$2:$G$75=$E52)*(Rates_data!$E$2:$E$75=$C52)*(Rates_data!$Y$2:$Y$75=1)*(Rates_data!$P$2:$P$75<>""),Rates_data!$P$2:$P$75))} -> 1116.23 | I52: =_xlfn.MAXIFS(Rates_data!$P$2:$P$75,Rates_data!$B$2:$B$75,$A52,Rates_data!$D$2:$D$75,$B52,Rates_data!$E$2:$E$75,$C52,Rates_data!$G$2:$G$75,$E52,Rates_data!$Y$2:$Y$75,1) -> 1141.22 | J52: =IF(F52=0,"",SUMIFS(Rates_data!$R$2:$R$75,Rates_data!$B$2:$B$75,$A52,Rates_data!$D$2:$D$75,$B52,Rates_data!$E$2:$E$75,$C52,Rates_data!$G$2:$G$75,$E52,Rates_data!$Y$2:$Y$75,1)/F52) -> 0 | K52: {=IF(COUNTIFS(Rates_data!$B$2:$B$75,$A52,Rates_data!$D$2:$D$75,$B52,Rates_data!$E$2:$E$75,$C52,Rates_data!$G$2:$G$75,$E52,Rates_data!$Y$2:$Y$75,1,Rates_data!$S$2:$S$75,"<>")=0,"",MEDIAN(IF((Rates_data!$B$2:$B$75=$A52)*(Rates_data!$D$2:$D$75=$B52)*(Rates_data!$G$2:$G$75=$E52)*(Rates_data!$E$2:$E$75=$C52)*(Rates_data!$Y$2:$Y$75=1)*(Rates_data!$S$2:$S$75<>""),Rates_data!$S$2:$S$75)))} | L52: =IF(COUNTIFS(Rates_data!$B$2:$B$75,$A52,Rates_data!$D$2:$D$75,$B52,Rates_data!$E$2:$E$75,$C52,Rates_data!$G$2:$G$75,$E52,Rates_data!$Y$2:$Y$75,1,Rates_data!$T$2:$T$75,"<>")=0,"",_xlfn.MINIFS(Rates_data!$T$2:$T$75,Rates_data!$B$2:$B$75,$A52,Rates_data!$D$2:$D$75,$B52,Rates_data!$E$2:$E$75,$C52,Rates_data!$G$2:$G$75,$E52,Rates_data!$Y$2:$Y$75,1)) | M52: =IF(COUNTIFS(Rates_data!$B$2:$B$75,$A52,Rates_data!$D$2:$D$75,$B52,Rates_data!$E$2:$E$75,$C52,Rates_data!$G$2:$G$75,$E52,Rates_data!$Y$2:$Y$75,1,Rates_data!$U$2:$U$75,"<>")=0,"",_xlfn.MAXIFS(Rates_data!$U$2:$U$75,Rates_data!$B$2:$B$75,$A52,Rates_data!$D$2:$D$75,$B52,Rates_data!$E$2:$E$75,$C52,Rates_data!$G$2:$G$75,$E52,Rates_data!$Y$2:$Y$75,1)) | O52: =IF(K52<>"",K52,H52) -> 1116.23 | P52: =IF(K52<>"","median allowed","median negotiated") -> median negotiated
A53: Beth Israel Deaconess Medical Center | B53: 93660 | C53: Harvard Pilgrim Healthcare | D53: Harvard Pilgrim / Point32Health | E53: Commercial | F53: =COUNTIFS(Rates_data!$B$2:$B$75,$A53,Rates_data!$D$2:$D$75,$B53,Rates_data!$E$2:$E$75,$C53,Rates_data!$G$2:$G$75,$E53,Rates_data!$Y$2:$Y$75,1) -> 1 | G53: =_xlfn.MINIFS(Rates_data!$P$2:$P$75,Rates_data!$B$2:$B$75,$A53,Rates_data!$D$2:$D$75,$B53,Rates_data!$E$2:$E$75,$C53,Rates_data!$G$2:$G$75,$E53,Rates_data!$Y$2:$Y$75,1) -> 1329.39 | H53: {=MEDIAN(IF((Rates_data!$B$2:$B$75=$A53)*(Rates_data!$D$2:$D$75=$B53)*(Rates_data!$G$2:$G$75=$E53)*(Rates_data!$E$2:$E$75=$C53)*(Rates_data!$Y$2:$Y$75=1)*(Rates_data!$P$2:$P$75<>""),Rates_data!$P$2:$P$75))} -> 1329.39 | I53: =_xlfn.MAXIFS(Rates_data!$P$2:$P$75,Rates_data!$B$2:$B$75,$A53,Rates_data!$D$2:$D$75,$B53,Rates_data!$E$2:$E$75,$C53,Rates_data!$G$2:$G$75,$E53,Rates_data!$Y$2:$Y$75,1) -> 1329.39 | J53: =IF(F53=0,"",SUMIFS(Rates_data!$R$2:$R$75,Rates_data!$B$2:$B$75,$A53,Rates_data!$D$2:$D$75,$B53,Rates_data!$E$2:$E$75,$C53,Rates_data!$G$2:$G$75,$E53,Rates_data!$Y$2:$Y$75,1)/F53) -> 0 | K53: {=IF(COUNTIFS(Rates_data!$B$2:$B$75,$A53,Rates_data!$D$2:$D$75,$B53,Rates_data!$E$2:$E$75,$C53,Rates_data!$G$2:$G$75,$E53,Rates_data!$Y$2:$Y$75,1,Rates_data!$S$2:$S$75,"<>")=0,"",MEDIAN(IF((Rates_data!$B$2:$B$75=$A53)*(Rates_data!$D$2:$D$75=$B53)*(Rates_data!$G$2:$G$75=$E53)*(Rates_data!$E$2:$E$75=$C53)*(Rates_data!$Y$2:$Y$75=1)*(Rates_data!$S$2:$S$75<>""),Rates_data!$S$2:$S$75)))} | L53: =IF(COUNTIFS(Rates_data!$B$2:$B$75,$A53,Rates_data!$D$2:$D$75,$B53,Rates_data!$E$2:$E$75,$C53,Rates_data!$G$2:$G$75,$E53,Rates_data!$Y$2:$Y$75,1,Rates_data!$T$2:$T$75,"<>")=0,"",_xlfn.MINIFS(Rates_data!$T$2:$T$75,Rates_data!$B$2:$B$75,$A53,Rates_data!$D$2:$D$75,$B53,Rates_data!$E$2:$E$75,$C53,Rates_data!$G$2:$G$75,$E53,Rates_data!$Y$2:$Y$75,1)) | M53: =IF(COUNTIFS(Rates_data!$B$2:$B$75,$A53,Rates_data!$D$2:$D$75,$B53,Rates_data!$E$2:$E$75,$C53,Rates_data!$G$2:$G$75,$E53,Rates_data!$Y$2:$Y$75,1,Rates_data!$U$2:$U$75,"<>")=0,"",_xlfn.MAXIFS(Rates_data!$U$2:$U$75,Rates_data!$B$2:$B$75,$A53,Rates_data!$D$2:$D$75,$B53,Rates_data!$E$2:$E$75,$C53,Rates_data!$G$2:$G$75,$E53,Rates_data!$Y$2:$Y$75,1)) | O53: =IF(K53<>"",K53,H53) -> 1329.39 | P53: =IF(K53<>"","median allowed","median negotiated") -> median negotiated
A54: Beth Israel Deaconess Medical Center | B54: 93660 | C54: Unicare | D54: Unicare (GIC) | E54: Commercial | F54: =COUNTIFS(Rates_data!$B$2:$B$75,$A54,Rates_data!$D$2:$D$75,$B54,Rates_data!$E$2:$E$75,$C54,Rates_data!$G$2:$G$75,$E54,Rates_data!$Y$2:$Y$75,1) -> 1 | G54: =_xlfn.MINIFS(Rates_data!$P$2:$P$75,Rates_data!$B$2:$B$75,$A54,Rates_data!$D$2:$D$75,$B54,Rates_data!$E$2:$E$75,$C54,Rates_data!$G$2:$G$75,$E54,Rates_data!$Y$2:$Y$75,1) -> 502.78 | H54: {=MEDIAN(IF((Rates_data!$B$2:$B$75=$A54)*(Rates_data!$D$2:$D$75=$B54)*(Rates_data!$G$2:$G$75=$E54)*(Rates_data!$E$2:$E$75=$C54)*(Rates_data!$Y$2:$Y$75=1)*(Rates_data!$P$2:$P$75<>""),Rates_data!$P$2:$P$75))} -> 502.78 | I54: =_xlfn.MAXIFS(Rates_data!$P$2:$P$75,Rates_data!$B$2:$B$75,$A54,Rates_data!$D$2:$D$75,$B54,Rates_data!$E$2:$E$75,$C54,Rates_data!$G$2:$G$75,$E54,Rates_data!$Y$2:$Y$75,1) -> 502.78 | J54: =IF(F54=0,"",SUMIFS(Rates_data!$R$2:$R$75,Rates_data!$B$2:$B$75,$A54,Rates_data!$D$2:$D$75,$B54,Rates_data!$E$2:$E$75,$C54,Rates_data!$G$2:$G$75,$E54,Rates_data!$Y$2:$Y$75,1)/F54) -> 0 | K54: {=IF(COUNTIFS(Rates_data!$B$2:$B$75,$A54,Rates_data!$D$2:$D$75,$B54,Rates_data!$E$2:$E$75,$C54,Rates_data!$G$2:$G$75,$E54,Rates_data!$Y$2:$Y$75,1,Rates_data!$S$2:$S$75,"<>")=0,"",MEDIAN(IF((Rates_data!$B$2:$B$75=$A54)*(Rates_data!$D$2:$D$75=$B54)*(Rates_data!$G$2:$G$75=$E54)*(Rates_data!$E$2:$E$75=$C54)*(Rates_data!$Y$2:$Y$75=1)*(Rates_data!$S$2:$S$75<>""),Rates_data!$S$2:$S$75)))} | L54: =IF(COUNTIFS(Rates_data!$B$2:$B$75,$A54,Rates_data!$D$2:$D$75,$B54,Rates_data!$E$2:$E$75,$C54,Rates_data!$G$2:$G$75,$E54,Rates_data!$Y$2:$Y$75,1,Rates_data!$T$2:$T$75,"<>")=0,"",_xlfn.MINIFS(Rates_data!$T$2:$T$75,Rates_data!$B$2:$B$75,$A54,Rates_data!$D$2:$D$75,$B54,Rates_data!$E$2:$E$75,$C54,Rates_data!$G$2:$G$75,$E54,Rates_data!$Y$2:$Y$75,1)) | M54: =IF(COUNTIFS(Rates_data!$B$2:$B$75,$A54,Rates_data!$D$2:$D$75,$B54,Rates_data!$E$2:$E$75,$C54,Rates_data!$G$2:$G$75,$E54,Rates_data!$Y$2:$Y$75,1,Rates_data!$U$2:$U$75,"<>")=0,"",_xlfn.MAXIFS(Rates_data!$U$2:$U$75,Rates_data!$B$2:$B$75,$A54,Rates_data!$D$2:$D$75,$B54,Rates_data!$E$2:$E$75,$C54,Rates_data!$G$2:$G$75,$E54,Rates_data!$Y$2:$Y$75,1)) | O54: =IF(K54<>"",K54,H54) -> 502.78 | P54: =IF(K54<>"","median allowed","median negotiated") -> median negotiated
A55: Beth Israel Deaconess Medical Center | B55: 95921 | C55: BCBS | D55: Blue Cross Blue Shield of MA | E55: Commercial | F55: =COUNTIFS(Rates_data!$B$2:$B$75,$A55,Rates_data!$D$2:$D$75,$B55,Rates_data!$E$2:$E$75,$C55,Rates_data!$G$2:$G$75,$E55,Rates_data!$Y$2:$Y$75,1) -> 2 | G55: =_xlfn.MINIFS(Rates_data!$P$2:$P$75,Rates_data!$B$2:$B$75,$A55,Rates_data!$D$2:$D$75,$B55,Rates_data!$E$2:$E$75,$C55,Rates_data!$G$2:$G$75,$E55,Rates_data!$Y$2:$Y$75,1) -> 325.87 | H55: {=MEDIAN(IF((Rates_data!$B$2:$B$75=$A55)*(Rates_data!$D$2:$D$75=$B55)*(Rates_data!$G$2:$G$75=$E55)*(Rates_data!$E$2:$E$75=$C55)*(Rates_data!$Y$2:$Y$75=1)*(Rates_data!$P$2:$P$75<>""),Rates_data!$P$2:$P$75))} -> 333.33 | I55: =_xlfn.MAXIFS(Rates_data!$P$2:$P$75,Rates_data!$B$2:$B$75,$A55,Rates_data!$D$2:$D$75,$B55,Rates_data!$E$2:$E$75,$C55,Rates_data!$G$2:$G$75,$E55,Rates_data!$Y$2:$Y$75,1) -> 340.79 | J55: =IF(F55=0,"",SUMIFS(Rates_data!$R$2:$R$75,Rates_data!$B$2:$B$75,$A55,Rates_data!$D$2:$D$75,$B55,Rates_data!$E$2:$E$75,$C55,Rates_data!$G$2:$G$75,$E55,Rates_data!$Y$2:$Y$75,1)/F55) -> 0 | K55: {=IF(COUNTIFS(Rates_data!$B$2:$B$75,$A55,Rates_data!$D$2:$D$75,$B55,Rates_data!$E$2:$E$75,$C55,Rates_data!$G$2:$G$75,$E55,Rates_data!$Y$2:$Y$75,1,Rates_data!$S$2:$S$75,"<>")=0,"",MEDIAN(IF((Rates_data!$B$2:$B$75=$A55)*(Rates_data!$D$2:$D$75=$B55)*(Rates_data!$G$2:$G$75=$E55)*(Rates_data!$E$2:$E$75=$C55)*(Rates_data!$Y$2:$Y$75=1)*(Rates_data!$S$2:$S$75<>""),Rates_data!$S$2:$S$75)))} | L55: =IF(COUNTIFS(Rates_data!$B$2:$B$75,$A55,Rates_data!$D$2:$D$75,$B55,Rates_data!$E$2:$E$75,$C55,Rates_data!$G$2:$G$75,$E55,Rates_data!$Y$2:$Y$75,1,Rates_data!$T$2:$T$75,"<>")=0,"",_xlfn.MINIFS(Rates_data!$T$2:$T$75,Rates_data!$B$2:$B$75,$A55,Rates_data!$D$2:$D$75,$B55,Rates_data!$E$2:$E$75,$C55,Rates_data!$G$2:$G$75,$E55,Rates_data!$Y$2:$Y$75,1)) | M55: =IF(COUNTIFS(Rates_data!$B$2:$B$75,$A55,Rates_data!$D$2:$D$75,$B55,Rates_data!$E$2:$E$75,$C55,Rates_data!$G$2:$G$75,$E55,Rates_data!$Y$2:$Y$75,1,Rates_data!$U$2:$U$75,"<>")=0,"",_xlfn.MAXIFS(Rates_data!$U$2:$U$75,Rates_data!$B$2:$B$75,$A55,Rates_data!$D$2:$D$75,$B55,Rates_data!$E$2:$E$75,$C55,Rates_data!$G$2:$G$75,$E55,Rates_data!$Y$2:$Y$75,1)) | O55: =IF(K55<>"",K55,H55) -> 333.33 | P55: =IF(K55<>"","median allowed","median negotiated") -> median negotiated
A56: Beth Israel Deaconess Medical Center | B56: 95921 | C56: Harvard Pilgrim Healthcare | D56: Harvard Pilgrim / Point32Health | E56: Commercial | F56: =COUNTIFS(Rates_data!$B$2:$B$75,$A56,Rates_data!$D$2:$D$75,$B56,Rates_data!$E$2:$E$75,$C56,Rates_data!$G$2:$G$75,$E56,Rates_data!$Y$2:$Y$75,1) -> 1 | G56: =_xlfn.MINIFS(Rates_data!$P$2:$P$75,Rates_data!$B$2:$B$75,$A56,Rates_data!$D$2:$D$75,$B56,Rates_data!$E$2:$E$75,$C56,Rates_data!$G$2:$G$75,$E56,Rates_data!$Y$2:$Y$75,1) -> 396.97 | H56: {=MEDIAN(IF((Rates_data!$B$2:$B$75=$A56)*(Rates_data!$D$2:$D$75=$B56)*(Rates_data!$G$2:$G$75=$E56)*(Rates_data!$E$2:$E$75=$C56)*(Rates_data!$Y$2:$Y$75=1)*(Rates_data!$P$2:$P$75<>""),Rates_data!$P$2:$P$75))} -> 396.97 | I56: =_xlfn.MAXIFS(Rates_data!$P$2:$P$75,Rates_data!$B$2:$B$75,$A56,Rates_data!$D$2:$D$75,$B56,Rates_data!$E$2:$E$75,$C56,Rates_data!$G$2:$G$75,$E56,Rates_data!$Y$2:$Y$75,1) -> 396.97 | J56: =IF(F56=0,"",SUMIFS(Rates_data!$R$2:$R$75,Rates_data!$B$2:$B$75,$A56,Rates_data!$D$2:$D$75,$B56,Rates_data!$E$2:$E$75,$C56,Rates_data!$G$2:$G$75,$E56,Rates_data!$Y$2:$Y$75,1)/F56) -> 0 | K56: {=IF(COUNTIFS(Rates_data!$B$2:$B$75,$A56,Rates_data!$D$2:$D$75,$B56,Rates_data!$E$2:$E$75,$C56,Rates_data!$G$2:$G$75,$E56,Rates_data!$Y$2:$Y$75,1,Rates_data!$S$2:$S$75,"<>")=0,"",MEDIAN(IF((Rates_data!$B$2:$B$75=$A56)*(Rates_data!$D$2:$D$75=$B56)*(Rates_data!$G$2:$G$75=$E56)*(Rates_data!$E$2:$E$75=$C56)*(Rates_data!$Y$2:$Y$75=1)*(Rates_data!$S$2:$S$75<>""),Rates_data!$S$2:$S$75)))} | L56: =IF(COUNTIFS(Rates_data!$B$2:$B$75,$A56,Rates_data!$D$2:$D$75,$B56,Rates_data!$E$2:$E$75,$C56,Rates_data!$G$2:$G$75,$E56,Rates_data!$Y$2:$Y$75,1,Rates_data!$T$2:$T$75,"<>")=0,"",_xlfn.MINIFS(Rates_data!$T$2:$T$75,Rates_data!$B$2:$B$75,$A56,Rates_data!$D$2:$D$75,$B56,Rates_data!$E$2:$E$75,$C56,Rates_data!$G$2:$G$75,$E56,Rates_data!$Y$2:$Y$75,1)) | M56: =IF(COUNTIFS(Rates_data!$B$2:$B$75,$A56,Rates_data!$D$2:$D$75,$B56,Rates_data!$E$2:$E$75,$C56,Rates_data!$G$2:$G$75,$E56,Rates_data!$Y$2:$Y$75,1,Rates_data!$U$2:$U$75,"<>")=0,"",_xlfn.MAXIFS(Rates_data!$U$2:$U$75,Rates_data!$B$2:$B$75,$A56,Rates_data!$D$2:$D$75,$B56,Rates_data!$E$2:$E$75,$C56,Rates_data!$G$2:$G$75,$E56,Rates_data!$Y$2:$Y$75,1)) | O56: =IF(K56<>"",K56,H56) -> 396.97 | P56: =IF(K56<>"","median allowed","median negotiated") -> median negotiated
A57: Beth Israel Deaconess Medical Center | B57: 95922 | C57: BCBS | D57: Blue Cross Blue Shield of MA | E57: Commercial | F57: =COUNTIFS(Rates_data!$B$2:$B$75,$A57,Rates_data!$D$2:$D$75,$B57,Rates_data!$E$2:$E$75,$C57,Rates_data!$G$2:$G$75,$E57,Rates_data!$Y$2:$Y$75,1) -> 2 | G57: =_xlfn.MINIFS(Rates_data!$P$2:$P$75,Rates_data!$B$2:$B$75,$A57,Rates_data!$D$2:$D$75,$B57,Rates_data!$E$2:$E$75,$C57,Rates_data!$G$2:$G$75,$E57,Rates_data!$Y$2:$Y$75,1) -> 255.23 | H57: {=MEDIAN(IF((Rates_data!$B$2:$B$75=$A57)*(Rates_data!$D$2:$D$75=$B57)*(Rates_data!$G$2:$G$75=$E57)*(Rates_data!$E$2:$E$75=$C57)*(Rates_data!$Y$2:$Y$75=1)*(Rates_data!$P$2:$P$75<>""),Rates_data!$P$2:$P$75))} -> 261.075 | I57: =_xlfn.MAXIFS(Rates_data!$P$2:$P$75,Rates_data!$B$2:$B$75,$A57,Rates_data!$D$2:$D$75,$B57,Rates_data!$E$2:$E$75,$C57,Rates_data!$G$2:$G$75,$E57,Rates_data!$Y$2:$Y$75,1) -> 266.92 | J57: =IF(F57=0,"",SUMIFS(Rates_data!$R$2:$R$75,Rates_data!$B$2:$B$75,$A57,Rates_data!$D$2:$D$75,$B57,Rates_data!$E$2:$E$75,$C57,Rates_data!$G$2:$G$75,$E57,Rates_data!$Y$2:$Y$75,1)/F57) -> 0 | K57: {=IF(COUNTIFS(Rates_data!$B$2:$B$75,$A57,Rates_data!$D$2:$D$75,$B57,Rates_data!$E$2:$E$75,$C57,Rates_data!$G$2:$G$75,$E57,Rates_data!$Y$2:$Y$75,1,Rates_data!$S$2:$S$75,"<>")=0,"",MEDIAN(IF((Rates_data!$B$2:$B$75=$A57)*(Rates_data!$D$2:$D$75=$B57)*(Rates_data!$G$2:$G$75=$E57)*(Rates_data!$E$2:$E$75=$C57)*(Rates_data!$Y$2:$Y$75=1)*(Rates_data!$S$2:$S$75<>""),Rates_data!$S$2:$S$75)))} | L57: =IF(COUNTIFS(Rates_data!$B$2:$B$75,$A57,Rates_data!$D$2:$D$75,$B57,Rates_data!$E$2:$E$75,$C57,Rates_data!$G$2:$G$75,$E57,Rates_data!$Y$2:$Y$75,1,Rates_data!$T$2:$T$75,"<>")=0,"",_xlfn.MINIFS(Rates_data!$T$2:$T$75,Rates_data!$B$2:$B$75,$A57,Rates_data!$D$2:$D$75,$B57,Rates_data!$E$2:$E$75,$C57,Rates_data!$G$2:$G$75,$E57,Rates_data!$Y$2:$Y$75,1)) | M57: =IF(COUNTIFS(Rates_data!$B$2:$B$75,$A57,Rates_data!$D$2:$D$75,$B57,Rates_data!$E$2:$E$75,$C57,Rates_data!$G$2:$G$75,$E57,Rates_data!$Y$2:$Y$75,1,Rates_data!$U$2:$U$75,"<>")=0,"",_xlfn.MAXIFS(Rates_data!$U$2:$U$75,Rates_data!$B$2:$B$75,$A57,Rates_data!$D$2:$D$75,$B57,Rates_data!$E$2:$E$75,$C57,Rates_data!$G$2:$G$75,$E57,Rates_data!$Y$2:$Y$75,1)) | O57: =IF(K57<>"",K57,H57) -> 261.075 | P57: =IF(K57<>"","median allowed","median negotiated") -> median negotiated
A58: Beth Israel Deaconess Medical Center | B58: 95922 | C58: Harvard Pilgrim Healthcare | D58: Harvard Pilgrim / Point32Health | E58: Commercial | F58: =COUNTIFS(Rates_data!$B$2:$B$75,$A58,Rates_data!$D$2:$D$75,$B58,Rates_data!$E$2:$E$75,$C58,Rates_data!$G$2:$G$75,$E58,Rates_data!$Y$2:$Y$75,1) -> 1 | G58: =_xlfn.MINIFS(Rates_data!$P$2:$P$75,Rates_data!$B$2:$B$75,$A58,Rates_data!$D$2:$D$75,$B58,Rates_data!$E$2:$E$75,$C58,Rates_data!$G$2:$G$75,$E58,Rates_data!$Y$2:$Y$75,1) -> 310.92 | H58: {=MEDIAN(IF((Rates_data!$B$2:$B$75=$A58)*(Rates_data!$D$2:$D$75=$B58)*(Rates_data!$G$2:$G$75=$E58)*(Rates_data!$E$2:$E$75=$C58)*(Rates_data!$Y$2:$Y$75=1)*(Rates_data!$P$2:$P$75<>""),Rates_data!$P$2:$P$75))} -> 310.92 | I58: =_xlfn.MAXIFS(Rates_data!$P$2:$P$75,Rates_data!$B$2:$B$75,$A58,Rates_data!$D$2:$D$75,$B58,Rates_data!$E$2:$E$75,$C58,Rates_data!$G$2:$G$75,$E58,Rates_data!$Y$2:$Y$75,1) -> 310.92 | J58: =IF(F58=0,"",SUMIFS(Rates_data!$R$2:$R$75,Rates_data!$B$2:$B$75,$A58,Rates_data!$D$2:$D$75,$B58,Rates_data!$E$2:$E$75,$C58,Rates_data!$G$2:$G$75,$E58,Rates_data!$Y$2:$Y$75,1)/F58) -> 0 | K58: {=IF(COUNTIFS(Rates_data!$B$2:$B$75,$A58,Rates_data!$D$2:$D$75,$B58,Rates_data!$E$2:$E$75,$C58,Rates_data!$G$2:$G$75,$E58,Rates_data!$Y$2:$Y$75,1,Rates_data!$S$2:$S$75,"<>")=0,"",MEDIAN(IF((Rates_data!$B$2:$B$75=$A58)*(Rates_data!$D$2:$D$75=$B58)*(Rates_data!$G$2:$G$75=$E58)*(Rates_data!$E$2:$E$75=$C58)*(Rates_data!$Y$2:$Y$75=1)*(Rates_data!$S$2:$S$75<>""),Rates_data!$S$2:$S$75)))} | L58: =IF(COUNTIFS(Rates_data!$B$2:$B$75,$A58,Rates_data!$D$2:$D$75,$B58,Rates_data!$E$2:$E$75,$C58,Rates_data!$G$2:$G$75,$E58,Rates_data!$Y$2:$Y$75,1,Rates_data!$T$2:$T$75,"<>")=0,"",_xlfn.MINIFS(Rates_data!$T$2:$T$75,Rates_data!$B$2:$B$75,$A58,Rates_data!$D$2:$D$75,$B58,Rates_data!$E$2:$E$75,$C58,Rates_data!$G$2:$G$75,$E58,Rates_data!$Y$2:$Y$75,1)) | M58: =IF(COUNTIFS(Rates_data!$B$2:$B$75,$A58,Rates_data!$D$2:$D$75,$B58,Rates_data!$E$2:$E$75,$C58,Rates_data!$G$2:$G$75,$E58,Rates_data!$Y$2:$Y$75,1,Rates_data!$U$2:$U$75,"<>")=0,"",_xlfn.MAXIFS(Rates_data!$U$2:$U$75,Rates_data!$B$2:$B$75,$A58,Rates_data!$D$2:$D$75,$B58,Rates_data!$E$2:$E$75,$C58,Rates_data!$G$2:$G$75,$E58,Rates_data!$Y$2:$Y$75,1)) | O58: =IF(K58<>"",K58,H58) -> 310.92 | P58: =IF(K58<>"","median allowed","median negotiated") -> median negotiated
A59: Beth Israel Deaconess Medical Center | B59: 95923 | C59: BCBS | D59: Blue Cross Blue Shield of MA | E59: Commercial | F59: =COUNTIFS(Rates_data!$B$2:$B$75,$A59,Rates_data!$D$2:$D$75,$B59,Rates_data!$E$2:$E$75,$C59,Rates_data!$G$2:$G$75,$E59,Rates_data!$Y$2:$Y$75,1) -> 2 | G59: =_xlfn.MINIFS(Rates_data!$P$2:$P$75,Rates_data!$B$2:$B$75,$A59,Rates_data!$D$2:$D$75,$B59,Rates_data!$E$2:$E$75,$C59,Rates_data!$G$2:$G$75,$E59,Rates_data!$Y$2:$Y$75,1) -> 255.23 | H59: {=MEDIAN(IF((Rates_data!$B$2:$B$75=$A59)*(Rates_data!$D$2:$D$75=$B59)*(Rates_data!$G$2:$G$75=$E59)*(Rates_data!$E$2:$E$75=$C59)*(Rates_data!$Y$2:$Y$75=1)*(Rates_data!$P$2:$P$75<>""),Rates_data!$P$2:$P$75))} -> 261.075 | I59: =_xlfn.MAXIFS(Rates_data!$P$2:$P$75,Rates_data!$B$2:$B$75,$A59,Rates_data!$D$2:$D$75,$B59,Rates_data!$E$2:$E$75,$C59,Rates_data!$G$2:$G$75,$E59,Rates_data!$Y$2:$Y$75,1) -> 266.92 | J59: =IF(F59=0,"",SUMIFS(Rates_data!$R$2:$R$75,Rates_data!$B$2:$B$75,$A59,Rates_data!$D$2:$D$75,$B59,Rates_data!$E$2:$E$75,$C59,Rates_data!$G$2:$G$75,$E59,Rates_data!$Y$2:$Y$75,1)/F59) -> 0 | K59: {=IF(COUNTIFS(Rates_data!$B$2:$B$75,$A59,Rates_data!$D$2:$D$75,$B59,Rates_data!$E$2:$E$75,$C59,Rates_data!$G$2:$G$75,$E59,Rates_data!$Y$2:$Y$75,1,Rates_data!$S$2:$S$75,"<>")=0,"",MEDIAN(IF((Rates_data!$B$2:$B$75=$A59)*(Rates_data!$D$2:$D$75=$B59)*(Rates_data!$G$2:$G$75=$E59)*(Rates_data!$E$2:$E$75=$C59)*(Rates_data!$Y$2:$Y$75=1)*(Rates_data!$S$2:$S$75<>""),Rates_data!$S$2:$S$75)))} | L59: =IF(COUNTIFS(Rates_data!$B$2:$B$75,$A59,Rates_data!$D$2:$D$75,$B59,Rates_data!$E$2:$E$75,$C59,Rates_data!$G$2:$G$75,$E59,Rates_data!$Y$2:$Y$75,1,Rates_data!$T$2:$T$75,"<>")=0,"",_xlfn.MINIFS(Rates_data!$T$2:$T$75,Rates_data!$B$2:$B$75,$A59,Rates_data!$D$2:$D$75,$B59,Rates_data!$E$2:$E$75,$C59,Rates_data!$G$2:$G$75,$E59,Rates_data!$Y$2:$Y$75,1)) | M59: =IF(COUNTIFS(Rates_data!$B$2:$B$75,$A59,Rates_data!$D$2:$D$75,$B59,Rates_data!$E$2:$E$75,$C59,Rates_data!$G$2:$G$75,$E59,Rates_data!$Y$2:$Y$75,1,Rates_data!$U$2:$U$75,"<>")=0,"",_xlfn.MAXIFS(Rates_data!$U$2:$U$75,Rates_data!$B$2:$B$75,$A59,Rates_data!$D$2:$D$75,$B59,Rates_data!$E$2:$E$75,$C59,Rates_data!$G$2:$G$75,$E59,Rates_data!$Y$2:$Y$75,1)) | O59: =IF(K59<>"",K59,H59) -> 261.075 | P59: =IF(K59<>"","median allowed","median negotiated") -> median negotiated
A60: Beth Israel Deaconess Medical Center | B60: 95923 | C60: Harvard Pilgrim Healthcare | D60: Harvard Pilgrim / Point32Health | E60: Commercial | F60: =COUNTIFS(Rates_data!$B$2:$B$75,$A60,Rates_data!$D$2:$D$75,$B60,Rates_data!$E$2:$E$75,$C60,Rates_data!$G$2:$G$75,$E60,Rates_data!$Y$2:$Y$75,1) -> 1 | G60: =_xlfn.MINIFS(Rates_data!$P$2:$P$75,Rates_data!$B$2:$B$75,$A60,Rates_data!$D$2:$D$75,$B60,Rates_data!$E$2:$E$75,$C60,Rates_data!$G$2:$G$75,$E60,Rates_data!$Y$2:$Y$75,1) -> 310.92 | H60: {=MEDIAN(IF((Rates_data!$B$2:$B$75=$A60)*(Rates_data!$D$2:$D$75=$B60)*(Rates_data!$G$2:$G$75=$E60)*(Rates_data!$E$2:$E$75=$C60)*(Rates_data!$Y$2:$Y$75=1)*(Rates_data!$P$2:$P$75<>""),Rates_data!$P$2:$P$75))} -> 310.92 | I60: =_xlfn.MAXIFS(Rates_data!$P$2:$P$75,Rates_data!$B$2:$B$75,$A60,Rates_data!$D$2:$D$75,$B60,Rates_data!$E$2:$E$75,$C60,Rates_data!$G$2:$G$75,$E60,Rates_data!$Y$2:$Y$75,1) -> 310.92 | J60: =IF(F60=0,"",SUMIFS(Rates_data!$R$2:$R$75,Rates_data!$B$2:$B$75,$A60,Rates_data!$D$2:$D$75,$B60,Rates_data!$E$2:$E$75,$C60,Rates_data!$G$2:$G$75,$E60,Rates_data!$Y$2:$Y$75,1)/F60) -> 0 | K60: {=IF(COUNTIFS(Rates_data!$B$2:$B$75,$A60,Rates_data!$D$2:$D$75,$B60,Rates_data!$E$2:$E$75,$C60,Rates_data!$G$2:$G$75,$E60,Rates_data!$Y$2:$Y$75,1,Rates_data!$S$2:$S$75,"<>")=0,"",MEDIAN(IF((Rates_data!$B$2:$B$75=$A60)*(Rates_data!$D$2:$D$75=$B60)*(Rates_data!$G$2:$G$75=$E60)*(Rates_data!$E$2:$E$75=$C60)*(Rates_data!$Y$2:$Y$75=1)*(Rates_data!$S$2:$S$75<>""),Rates_data!$S$2:$S$75)))} | L60: =IF(COUNTIFS(Rates_data!$B$2:$B$75,$A60,Rates_data!$D$2:$D$75,$B60,Rates_data!$E$2:$E$75,$C60,Rates_data!$G$2:$G$75,$E60,Rates_data!$Y$2:$Y$75,1,Rates_data!$T$2:$T$75,"<>")=0,"",_xlfn.MINIFS(Rates_data!$T$2:$T$75,Rates_data!$B$2:$B$75,$A60,Rates_data!$D$2:$D$75,$B60,Rates_data!$E$2:$E$75,$C60,Rates_data!$G$2:$G$75,$E60,Rates_data!$Y$2:$Y$75,1)) | M60: =IF(COUNTIFS(Rates_data!$B$2:$B$75,$A60,Rates_data!$D$2:$D$75,$B60,Rates_data!$E$2:$E$75,$C60,Rates_data!$G$2:$G$75,$E60,Rates_data!$Y$2:$Y$75,1,Rates_data!$U$2:$U$75,"<>")=0,"",_xlfn.MAXIFS(Rates_data!$U$2:$U$75,Rates_data!$B$2:$B$75,$A60,Rates_data!$D$2:$D$75,$B60,Rates_data!$E$2:$E$75,$C60,Rates_data!$G$2:$G$75,$E60,Rates_data!$Y$2:$Y$75,1)) | O60: =IF(K60<>"",K60,H60) -> 310.92 | P60: =IF(K60<>"","median allowed","median negotiated") -> median negotiated
A61: Beth Israel Deaconess Medical Center | B61: 95924 | C61: BCBS | D61: Blue Cross Blue Shield of MA | E61: Commercial | F61: =COUNTIFS(Rates_data!$B$2:$B$75,$A61,Rates_data!$D$2:$D$75,$B61,Rates_data!$E$2:$E$75,$C61,Rates_data!$G$2:$G$75,$E61,Rates_data!$Y$2:$Y$75,1) -> 2 | G61: =_xlfn.MINIFS(Rates_data!$P$2:$P$75,Rates_data!$B$2:$B$75,$A61,Rates_data!$D$2:$D$75,$B61,Rates_data!$E$2:$E$75,$C61,Rates_data!$G$2:$G$75,$E61,Rates_data!$Y$2:$Y$75,1) -> 325.87 | H61: {=MEDIAN(IF((Rates_data!$B$2:$B$75=$A61)*(Rates_data!$D$2:$D$75=$B61)*(Rates_data!$G$2:$G$75=$E61)*(Rates_data!$E$2:$E$75=$C61)*(Rates_data!$Y$2:$Y$75=1)*(Rates_data!$P$2:$P$75<>""),Rates_data!$P$2:$P$75))} -> 333.33 | I61: =_xlfn.MAXIFS(Rates_data!$P$2:$P$75,Rates_data!$B$2:$B$75,$A61,Rates_data!$D$2:$D$75,$B61,Rates_data!$E$2:$E$75,$C61,Rates_data!$G$2:$G$75,$E61,Rates_data!$Y$2:$Y$75,1) -> 340.79 | J61: =IF(F61=0,"",SUMIFS(Rates_data!$R$2:$R$75,Rates_data!$B$2:$B$75,$A61,Rates_data!$D$2:$D$75,$B61,Rates_data!$E$2:$E$75,$C61,Rates_data!$G$2:$G$75,$E61,Rates_data!$Y$2:$Y$75,1)/F61) -> 0 | K61: {=IF(COUNTIFS(Rates_data!$B$2:$B$75,$A61,Rates_data!$D$2:$D$75,$B61,Rates_data!$E$2:$E$75,$C61,Rates_data!$G$2:$G$75,$E61,Rates_data!$Y$2:$Y$75,1,Rates_data!$S$2:$S$75,"<>")=0,"",MEDIAN(IF((Rates_data!$B$2:$B$75=$A61)*(Rates_data!$D$2:$D$75=$B61)*(Rates_data!$G$2:$G$75=$E61)*(Rates_data!$E$2:$E$75=$C61)*(Rates_data!$Y$2:$Y$75=1)*(Rates_data!$S$2:$S$75<>""),Rates_data!$S$2:$S$75)))} | L61: =IF(COUNTIFS(Rates_data!$B$2:$B$75,$A61,Rates_data!$D$2:$D$75,$B61,Rates_data!$E$2:$E$75,$C61,Rates_data!$G$2:$G$75,$E61,Rates_data!$Y$2:$Y$75,1,Rates_data!$T$2:$T$75,"<>")=0,"",_xlfn.MINIFS(Rates_data!$T$2:$T$75,Rates_data!$B$2:$B$75,$A61,Rates_data!$D$2:$D$75,$B61,Rates_data!$E$2:$E$75,$C61,Rates_data!$G$2:$G$75,$E61,Rates_data!$Y$2:$Y$75,1)) | M61: =IF(COUNTIFS(Rates_data!$B$2:$B$75,$A61,Rates_data!$D$2:$D$75,$B61,Rates_data!$E$2:$E$75,$C61,Rates_data!$G$2:$G$75,$E61,Rates_data!$Y$2:$Y$75,1,Rates_data!$U$2:$U$75,"<>")=0,"",_xlfn.MAXIFS(Rates_data!$U$2:$U$75,Rates_data!$B$2:$B$75,$A61,Rates_data!$D$2:$D$75,$B61,Rates_data!$E$2:$E$75,$C61,Rates_data!$G$2:$G$75,$E61,Rates_data!$Y$2:$Y$75,1)) | O61: =IF(K61<>"",K61,H61) -> 333.33 | P61: =IF(K61<>"","median allowed","median negotiated") -> median negotiated
A62: Beth Israel Deaconess Medical Center | B62: 95924 | C62: Harvard Pilgrim Healthcare | D62: Harvard Pilgrim / Point32Health | E62: Commercial | F62: =COUNTIFS(Rates_data!$B$2:$B$75,$A62,Rates_data!$D$2:$D$75,$B62,Rates_data!$E$2:$E$75,$C62,Rates_data!$G$2:$G$75,$E62,Rates_data!$Y$2:$Y$75,1) -> 1 | G62: =_xlfn.MINIFS(Rates_data!$P$2:$P$75,Rates_data!$B$2:$B$75,$A62,Rates_data!$D$2:$D$75,$B62,Rates_data!$E$2:$E$75,$C62,Rates_data!$G$2:$G$75,$E62,Rates_data!$Y$2:$Y$75,1) -> 396.97 | H62: {=MEDIAN(IF((Rates_data!$B$2:$B$75=$A62)*(Rates_data!$D$2:$D$75=$B62)*(Rates_data!$G$2:$G$75=$E62)*(Rates_data!$E$2:$E$75=$C62)*(Rates_data!$Y$2:$Y$75=1)*(Rates_data!$P$2:$P$75<>""),Rates_data!$P$2:$P$75))} -> 396.97 | I62: =_xlfn.MAXIFS(Rates_data!$P$2:$P$75,Rates_data!$B$2:$B$75,$A62,Rates_data!$D$2:$D$75,$B62,Rates_data!$E$2:$E$75,$C62,Rates_data!$G$2:$G$75,$E62,Rates_data!$Y$2:$Y$75,1) -> 396.97 | J62: =IF(F62=0,"",SUMIFS(Rates_data!$R$2:$R$75,Rates_data!$B$2:$B$75,$A62,Rates_data!$D$2:$D$75,$B62,Rates_data!$E$2:$E$75,$C62,Rates_data!$G$2:$G$75,$E62,Rates_data!$Y$2:$Y$75,1)/F62) -> 0 | K62: {=IF(COUNTIFS(Rates_data!$B$2:$B$75,$A62,Rates_data!$D$2:$D$75,$B62,Rates_data!$E$2:$E$75,$C62,Rates_data!$G$2:$G$75,$E62,Rates_data!$Y$2:$Y$75,1,Rates_data!$S$2:$S$75,"<>")=0,"",MEDIAN(IF((Rates_data!$B$2:$B$75=$A62)*(Rates_data!$D$2:$D$75=$B62)*(Rates_data!$G$2:$G$75=$E62)*(Rates_data!$E$2:$E$75=$C62)*(Rates_data!$Y$2:$Y$75=1)*(Rates_data!$S$2:$S$75<>""),Rates_data!$S$2:$S$75)))} | L62: =IF(COUNTIFS(Rates_data!$B$2:$B$75,$A62,Rates_data!$D$2:$D$75,$B62,Rates_data!$E$2:$E$75,$C62,Rates_data!$G$2:$G$75,$E62,Rates_data!$Y$2:$Y$75,1,Rates_data!$T$2:$T$75,"<>")=0,"",_xlfn.MINIFS(Rates_data!$T$2:$T$75,Rates_data!$B$2:$B$75,$A62,Rates_data!$D$2:$D$75,$B62,Rates_data!$E$2:$E$75,$C62,Rates_data!$G$2:$G$75,$E62,Rates_data!$Y$2:$Y$75,1)) | M62: =IF(COUNTIFS(Rates_data!$B$2:$B$75,$A62,Rates_data!$D$2:$D$75,$B62,Rates_data!$E$2:$E$75,$C62,Rates_data!$G$2:$G$75,$E62,Rates_data!$Y$2:$Y$75,1,Rates_data!$U$2:$U$75,"<>")=0,"",_xlfn.MAXIFS(Rates_data!$U$2:$U$75,Rates_data!$B$2:$B$75,$A62,Rates_data!$D$2:$D$75,$B62,Rates_data!$E$2:$E$75,$C62,Rates_data!$G$2:$G$75,$E62,Rates_data!$Y$2:$Y$75,1)) | O62: =IF(K62<>"",K62,H62) -> 396.97 | P62: =IF(K62<>"","median allowed","median negotiated") -> median negotiated

Sheet Battery
A1: Full autonomic battery: 95924 + 95923 facility rate, same payer/plan, plus approximate physician fee
A2: Physician fee = Medicare PC 142.57 (Reference). It is an APPROXIMATION: the physician group's negotiated rate is not published in hospital MRFs.
A4: Hospital | B4: Segment | C4: Payer | D4: Plan | E4: Pricing basis | F4: 95924 negotiated | G4: 95923 negotiated | H4: Facility battery (negotiated) | I4: 95924 median allowed | J4: 95923 median allowed | K4: Facility battery (allowed) | L4: Headline facility battery | M4: Headline basis | N4: Approx. physician fee (Medicare PC, approximation) | O4: Approx. total battery cost | P4: Note
A5: Massachusetts General Hospital | B5: Medicare FFS | C5: Medicare | E5: Hospital Medicare FFS row, OPPS packaging applied (95923 = 0) | F5: =Rates_data!P27 -> 369.77 | G5: =0 -> 0 | H5: =F5+G5 -> 369.77 | I5: =IF(Rates_data!S27="","",Rates_data!S27) -> 369.81 | J5: =0 -> 0 | K5: =IF(AND(I5<>"",J5<>""),I5+J5,"") -> 369.81 | L5: =IF(K5<>"",K5,H5) -> 369.81 | M5: =IF(K5<>"","median allowed","APC price") -> median allowed | N5: =Reference!$C$10 -> 142.57 | O5: =L5+N5 -> 512.38 | P5: 95923 is SI Q1: packaged with 95924 (SI S) on the same claim, no separate payment. Faulkner's own 95923 row says it is only paid if highest rate.
A6: Massachusetts General Hospital | B6: Medicare FFS | C6: Medicare | E6: Hospital 95924 row + OPPS national 95923 (not listed in file) | F6: =Rates_data!P27 -> 369.77 | G6: =Reference!$E$20 -> 135.93 | H6: =F6+G6 -> 505.7 | I6: =IF(Rates_data!S27="","",Rates_data!S27) -> 369.81 | K6: =IF(AND(I6<>"",J6<>""),I6+J6,"") | L6: =IF(K6<>"",K6,H6) -> 505.7 | M6: =IF(K6<>"","median allowed","APC price") -> APC price | N6: =Reference!$C$10 -> 142.57 | O6: =L6+N6 -> 648.27 | P6: File lists no Medicare row for 95923; national unadjusted Addendum B rate substituted and flagged.
A7: Massachusetts General Hospital | B7: Medicare FFS | C7: Medicare (reference) | E7: OPPS national (Addendum B), packaging applied (95923 = 0) | F7: =Reference!$E$21 -> 220.6 | G7: =0 -> 0 | H7: =F7+G7 -> 220.6 | L7: =IF(K7<>"",K7,H7) -> 220.6 | M7: =IF(K7<>"","median allowed","APC price") -> APC price | N7: =Reference!$C$10 -> 142.57 | O7: =L7+N7 -> 363.17 | P7: National, unadjusted for MA wage index.
